Workbook
Name Slicer_Customer: #N/A
Name Slicer_Department: #N/A
Name Slicer_Months: #N/A

Sheet Investment Report
B2: Aura Systems
B3: Investment Report
B5: Currency Converter
B6: Currency | C6: Rate
B7: USD | C7: 7.3
B8: EGP | C8: 1
B9: GBP | C9: 10
B10: EUR | C10: 8
B12: Expenses Report
B13: Ref | C13: Date | D13: Item | E13: Samer | F13: Simon | G13: Fadi | H13: Currency | I13: Rate | J13: Total (EGP)
B14: 1 | C14: 41960 | D14: Seed Money | E14: 0 | F14: 0 | G14: 27000 | H14: EGP | I14: =LOOKUP(Investment[[#This Row],[Currency]],Currency2[]) -> 1 | J14: =SUM(Investment[[#This Row],[Samer]:[Fadi]])*Investment[[#This Row],[Rate]] -> 27000
B15: 2 | C15: 42015 | D15: Seed Money | E15: 200 | F15: 0 | G15: 0 | H15: EGP | I15: =LOOKUP(Investment[[#This Row],[Currency]],Currency2[]) -> 1 | J15: =SUM(Investment[[#This Row],[Samer]:[Fadi]])*Investment[[#This Row],[Rate]] -> 200
B16: Total | E16: =SUMPRODUCT(Investment[Samer],Investment[Rate]) -> 200 | F16: =SUMPRODUCT(Investment[Simon],Investment[Rate]) -> 0 | G16: =SUMPRODUCT(Investment[Fadi],Investment[Rate]) -> 27000 | J16: =SUBTOTAL(109,Investment[Total (EGP)]) -> 27200

Sheet Dashboard
B2: Financial Dashboard | Y2: Performance Against Targets

Sheet plugo
B2: Aura Systems
B3: Expenses Log
B4: * All financial numbers are in EGP unless otherwise indicated
B6: Currency Converter
B7: Currency | C7: Rate
B8: EGP | C8: 1
B9: EUR | C9: 64 | K9: NA
B10: GBP | C10: 74 | K10: MISSING
B11: USD | C11: 58 | K11: DIGITAL
B13: Expenses Report | L13: Values in EGP
B14: Date | C14: Year | D14: Month | E14: Item | F14: Type | G14: Category | H14: Sub Category | I14: Customer | J14: Department | K14: Inv # | L14: Samer | M14: Simon | N14: Fadi | O14: Adel | P14: CapEx Cash | Q14: Cash | R14: Bank (QNB)EGP | S14: Margins | T14: Total (EGP) | U14: Absolute Total | V14: Comment | W14: Column1 | X14: Column2
B15: 45658 | C15: =YEAR(Finance[[#This Row],[Date]]) -> 2025 | D15: =MONTH(Finance[[#This Row],[Date]]) -> 1 | E15: Turni Contabo -Jan/25 | F15: Cost of Sales | G15: Hosting Spend | H15: External | I15: Turni | J15: 1 | L15: =57*51.78*1.25 -> 3689.325 | T15: =SUM(Finance[[#This Row],[Samer]:[Margins]]) -> 3689.325 | U15: =ABS(Finance[[#This Row],[Total (EGP)]]) -> 3689.325
B16: 45658 | C16: =YEAR(Finance[[#This Row],[Date]]) -> 2025 | D16: =MONTH(Finance[[#This Row],[Date]]) -> 1 | E16: Turni + Benefit (Jan/25) | F16: Cost of Sales | G16: Plugins | H16: External | I16: Turni | J16: 1 | L16: =17.66*2*50.5*1.05 -> 1872.843 | T16: =SUM(Finance[[#This Row],[Samer]:[Margins]]) -> 1872.843 | U16: =ABS(Finance[[#This Row],[Total (EGP)]]) -> 1872.843
B17: 45659 | C17: =YEAR(Finance[[#This Row],[Date]]) -> 2025 | D17: =MONTH(Finance[[#This Row],[Date]]) -> 1 | E17: Recover of unpaid fees | F17: OpEx | G17: Bank Charges | H17: Fees | I17: Aura | J17: 3 | R17: 100.02 | T17: =SUM(Finance[[#This Row],[Samer]:[Margins]]) -> 100.02 | U17: =ABS(Finance[[#This Row],[Total (EGP)]]) -> 100.02
B18: 45662 | C18: =YEAR(Finance[[#This Row],[Date]]) -> 2025 | D18: =MONTH(Finance[[#This Row],[Date]]) -> 1 | E18: Gas Jan/25 | F18: OpEx | G18: Utilities | H18: Gas | I18: Aura | J18: 3 | S18: 20 | T18: =SUM(Finance[[#This Row],[Samer]:[Margins]]) -> 20 | U18: =ABS(Finance[[#This Row],[Total (EGP)]]) -> 20
B19: 45663 | C19: =YEAR(Finance[[#This Row],[Date]]) -> 2025 | D19: =MONTH(Finance[[#This Row],[Date]]) -> 1 | E19: Nodust | F19: OpEx | G19: Consumables | H19: Higene | I19: Aura | J19: 3 | S19: 115 | T19: =SUM(Finance[[#This Row],[Samer]:[Margins]]) -> 115 | U19: =ABS(Finance[[#This Row],[Total (EGP)]]) -> 115
B20: 45665 | C20: =YEAR(Finance[[#This Row],[Date]]) -> 2025 | D20: =MONTH(Finance[[#This Row],[Date]]) -> 1 | E20: Adobe.com -Jan/25 | F20: OpEx | G20: Subscriptions | H20: Online Tools | I20: Aura | J20: 1 | L20: 599 | T20: =SUM(Finance[[#This Row],[Samer]:[Margins]]) -> 599 | U20: =ABS(Finance[[#This Row],[Total (EGP)]]) -> 599
B21: 45667 | C21: =YEAR(Finance[[#This Row],[Date]]) -> 2025 | D21: =MONTH(Finance[[#This Row],[Date]]) -> 1 | E21: Cloudways Jan/25-Paypal | F21: Cost of Sales | G21: Hosting Spend | H21: External | I21: ondoor | J21: 4 | L21: =78.28*50.5*1.25 -> 4941.425 | T21: =SUM(Finance[[#This Row],[Samer]:[Margins]]) -> 4941.425 | U21: =ABS(Finance[[#This Row],[Total (EGP)]]) -> 4941.425
B22: 45667 | C22: =YEAR(Finance[[#This Row],[Date]]) -> 2025 | D22: =MONTH(Finance[[#This Row],[Date]]) -> 1 | E22: CloudwaysLTD Mosta MT-Jan/25 | F22: Cost of Sales | G22: Hosting Spend | H22: External | I22: Smart Furniture | J22: 4 | L22: =153*50.5*1.25 -> 9658.125 | T22: =SUM(Finance[[#This Row],[Samer]:[Margins]]) -> 9658.125 | U22: =ABS(Finance[[#This Row],[Total (EGP)]]) -> 9658.125
B23: 45668 | C23: =YEAR(Finance[[#This Row],[Date]]) -> 2025 | D23: =MONTH(Finance[[#This Row],[Date]]) -> 1 | E23: Postman Basic (Monthly)- Jan/25 | F23: OpEx | G23: Subscriptions | H23: Online Tools | I23: Aura | J23: 4 | L23: 1761.081 | T23: =SUM(Finance[[#This Row],[Samer]:[Margins]]) -> 1761.081 | U23: =ABS(Finance[[#This Row],[Total (EGP)]]) -> 1761.081
B24: 45668 | C24: =YEAR(Finance[[#This Row],[Date]]) -> 2025 | D24: =MONTH(Finance[[#This Row],[Date]]) -> 1 | E24: ChatGPT Account Jan/25 | F24: OpEx | G24: Subscriptions | H24: Online Tools | I24: Aura | J24: 4 | L24: 699.9869 | T24: =SUM(Finance[[#This Row],[Samer]:[Margins]]) -> 699.9869 | U24: =ABS(Finance[[#This Row],[Total (EGP)]]) -> 699.9869
B25: 45669 | C25: =YEAR(Finance[[#This Row],[Date]]) -> 2025 | D25: =MONTH(Finance[[#This Row],[Date]]) -> 1 | E25: Atlassian-Jira(Jan/25) | F25: OpEx | G25: Subscriptions | H25: Online Tools | I25: Aura | J25: 1 | L25: =324.9*50.5*1.05 -> 17227.822 | T25: =SUM(Finance[[#This Row],[Samer]:[Margins]]) -> 17227.822 | U25: =ABS(Finance[[#This Row],[Total (EGP)]]) -> 17227.822
B26: 45669 | C26: =YEAR(Finance[[#This Row],[Date]]) -> 2025 | D26: =MONTH(Finance[[#This Row],[Date]]) -> 1 | E26: Charges CBX Package | F26: OpEx | G26: Bank Charges | H26: Fees | I26: Aura | J26: 3 | R26: 150 | T26: =SUM(Finance[[#This Row],[Samer]:[Margins]]) -> 150 | U26: =ABS(Finance[[#This Row],[Total (EGP)]]) -> 150
B27: 45671 | C27: =YEAR(Finance[[#This Row],[Date]]) -> 2025 | D27: =MONTH(Finance[[#This Row],[Date]]) -> 1 | E27: Bank Pays Samer | F27: Investment | G27: Balance Swap | H27: Bank Funding | I27: Aura | J27: 0 | L27: -132000 | R27: 132000 | T27: =SUM(Finance[[#This Row],[Samer]:[Margins]]) -> 0 | U27: =ABS(Finance[[#This Row],[Total (EGP)]]) -> 0
B28: 45671 | C28: =YEAR(Finance[[#This Row],[Date]]) -> 2025 | D28: =MONTH(Finance[[#This Row],[Date]]) -> 1 | E28: Samer Pays Fadi | F28: Investment | G28: Balance Swap | H28: Bank Funding | I28: Aura | J28: 0 | L28: 132000 | N28: -132000 | T28: =SUM(Finance[[#This Row],[Samer]:[Margins]]) -> 0 | U28: =ABS(Finance[[#This Row],[Total (EGP)]]) -> 0
B29: 45671 | C29: =YEAR(Finance[[#This Row],[Date]]) -> 2025 | D29: =MONTH(Finance[[#This Row],[Date]]) -> 1 | E29: Aura-demo Hosting(Jan/25) Aura.llc-Hetzner | F29: Cost of Sales | G29: Hosting Spend | H29: Internal | I29: Aura | J29: 4 | L29: =18.4*51.98*1.25 -> 1195.54 | T29: =SUM(Finance[[#This Row],[Samer]:[Margins]]) -> 1195.54 | U29: =ABS(Finance[[#This Row],[Total (EGP)]]) -> 1195.54
B30: 45671 | C30: =YEAR(Finance[[#This Row],[Date]]) -> 2025 | D30: =MONTH(Finance[[#This Row],[Date]]) -> 1 | E30: Turni Benefit Hosting(Jan/25)-Hetzner | F30: Cost of Sales | G30: Hosting Spend | H30: External | I30: Turni | J30: 1 | L30: =94.06*51.98*1.25 -> 6111.5485 | T30: =SUM(Finance[[#This Row],[Samer]:[Margins]]) -> 6111.5485 | U30: =ABS(Finance[[#This Row],[Total (EGP)]]) -> 6111.5485
B31: 45673 | C31: =YEAR(Finance[[#This Row],[Date]]) -> 2025 | D31: =MONTH(Finance[[#This Row],[Date]]) -> 1 | E31: GISS Landing page Final payment 60% (inv101308) | F31: Income | G31: Websites | H31: Bank | I31: منصة مصر للتعليم | J31: 4 | R31: -10350 | T31: =SUM(Finance[[#This Row],[Samer]:[Margins]]) -> -10350 | U31: =ABS(Finance[[#This Row],[Total (EGP)]]) -> 10350
B32: 45673 | C32: =YEAR(Finance[[#This Row],[Date]]) -> 2025 | D32: =MONTH(Finance[[#This Row],[Date]]) -> 1 | E32: GISS Landing page Final payment 60%-VAT | F32: Income | G32: Websites | H32: VAT | I32: منصة مصر للتعليم | J32: 4 | R32: =-10350*0.14 -> -1449 | T32: =SUM(Finance[[#This Row],[Samer]:[Margins]]) -> -1449 | U32: =ABS(Finance[[#This Row],[Total (EGP)]]) -> 1449
B33: 45673 | C33: =YEAR(Finance[[#This Row],[Date]]) -> 2025 | D33: =MONTH(Finance[[#This Row],[Date]]) -> 1 | E33: GISS Landing page Final payment 60% -Tax Deduction | F33: Tax | G33: Deduction Tax | H33: Bank | I33: منصة مصر للتعليم | J33: 4 | R33: =10350*0.03 -> 310.5 | T33: =SUM(Finance[[#This Row],[Samer]:[Margins]]) -> 310.5 | U33: =ABS(Finance[[#This Row],[Total (EGP)]]) -> 310.5
B34: 45673 | C34: =YEAR(Finance[[#This Row],[Date]]) -> 2025 | D34: =MONTH(Finance[[#This Row],[Date]]) -> 1 | E34: Cash Deposit Fees Hayah/EEP Payment | F34: OpEx | G34: Bank Charges | H34: Fees | I34: منصة مصر للتعليم | J34: 3 | R34: 10 | T34: =SUM(Finance[[#This Row],[Samer]:[Margins]]) -> 10 | U34: =ABS(Finance[[#This Row],[Total (EGP)]]) -> 10
B35: 45674 | C35: =YEAR(Finance[[#This Row],[Date]]) -> 2025 | D35: =MONTH(Finance[[#This Row],[Date]]) -> 1 | E35: Atlassian-Jira(Jan/25)-Bitbucket | F35: OpEx | G35: Subscriptions | H35: Online Tools | I35: Aura | J35: 1 | L35: =27*50.4*1.05 -> 1428.84 | T35: =SUM(Finance[[#This Row],[Samer]:[Margins]]) -> 1428.84 | U35: =ABS(Finance[[#This Row],[Total (EGP)]]) -> 1428.84
B36: 45676 | C36: =YEAR(Finance[[#This Row],[Date]]) -> 2025 | D36: =MONTH(Finance[[#This Row],[Date]]) -> 1 | E36: We Internet Recharge | F36: OpEx | G36: Internet | H36: We | I36: Aura | J36: 3 | R36: 500 | T36: =SUM(Finance[[#This Row],[Samer]:[Margins]]) -> 500 | U36: =ABS(Finance[[#This Row],[Total (EGP)]]) -> 500
B37: 45676 | C37: =YEAR(Finance[[#This Row],[Date]]) -> 2025 | D37: =MONTH(Finance[[#This Row],[Date]]) -> 1 | E37: We Internet Recharge | F37: OpEx | G37: Internet | H37: We | I37: Aura | J37: 3 | R37: 150 | T37: =SUM(Finance[[#This Row],[Samer]:[Margins]]) -> 150 | U37: =ABS(Finance[[#This Row],[Total (EGP)]]) -> 150
B38: 45677 | C38: =YEAR(Finance[[#This Row],[Date]]) -> 2025 | D38: =MONTH(Finance[[#This Row],[Date]]) -> 1 | E38: Domain Renewal (1year) aura.llc | F38: Cost of Sales | G38: Domains Spend | H38: Internal | I38: Aura | J38: 4 | L38: =39.16*50.4*1.05 -> 2072.3472 | T38: =SUM(Finance[[#This Row],[Samer]:[Margins]]) -> 2072.3472 | U38: =ABS(Finance[[#This Row],[Total (EGP)]]) -> 2072.3472
B39: 45678 | C39: =YEAR(Finance[[#This Row],[Date]]) -> 2025 | D39: =MONTH(Finance[[#This Row],[Date]]) -> 1 | E39: Samer Pays Margins | F39: Investment | G39: Balance Swap | H39: Cash Funding | I39: Aura | J39: 0 | L39: 2652.35 | S39: -2652.35 | T39: =SUM(Finance[[#This Row],[Samer]:[Margins]]) -> 0 | U39: =ABS(Finance[[#This Row],[Total (EGP)]]) -> 0
B40: 45679 | C40: =YEAR(Finance[[#This Row],[Date]]) -> 2025 | D40: =MONTH(Finance[[#This Row],[Date]]) -> 1 | E40: Zoom Subscription - Jan/25 | F40: OpEx | G40: Subscriptions | H40: Online Tools | I40: Aura | J40: 3 | L40: =15.99*50.4*1.05 -> 846.1908 | T40: =SUM(Finance[[#This Row],[Samer]:[Margins]]) -> 846.1908 | U40: =ABS(Finance[[#This Row],[Total (EGP)]]) -> 846.1908
B41: 45680 | C41: =YEAR(Finance[[#This Row],[Date]]) -> 2025 | D41: =MONTH(Finance[[#This Row],[Date]]) -> 1 | E41: Iscore payment الشركة المصرية للاستعلام الائتماني (inv101307) Q4 | F41: income | G41: Support Contracts | H41: Bank | I41: IScore | J41: 1 | R41: -38869.78 | T41: =SUM(Finance[[#This Row],[Samer]:[Margins]]) -> -38869.78 | U41: =ABS(Finance[[#This Row],[Total (EGP)]]) -> 38869.78
B42: 45680 | C42: =YEAR(Finance[[#This Row],[Date]]) -> 2025 | D42: =MONTH(Finance[[#This Row],[Date]]) -> 1 | E42: Iscore payment الشركة المصرية للاستعلام الائتماني-VAT | F42: Income | G42: Support Contracts | H42: VAT | I42: IScore | J42: 1 | R42: =-38869.78*0.14 -> -5441.7692 | T42: =SUM(Finance[[#This Row],[Samer]:[Margins]]) -> -5441.7692 | U42: =ABS(Finance[[#This Row],[Total (EGP)]]) -> 5441.7692
B43: 45680 | C43: =YEAR(Finance[[#This Row],[Date]]) -> 2025 | D43: =MONTH(Finance[[#This Row],[Date]]) -> 1 | E43: Iscore payment الشركة المصرية للاستعلام الائتماني- Tax Deduction | F43: Tax | G43: Deduction Tax | H43: Bank | I43: IScore | J43: 1 | R43: =38869.78*0.03 -> 1166.0934 | T43: =SUM(Finance[[#This Row],[Samer]:[Margins]]) -> 1166.0934 | U43: =ABS(Finance[[#This Row],[Total (EGP)]]) -> 1166.0934
...

Sheet Jan
A1: Date | B1: Item | C1: Debit | D1: Credit | E1: Balance
E2: 1504
A3: 45662 | B3: Various Consumables-City Market | C3: =2*48+25 -> 121 | E3: =E2-C3+D3 -> 1383
A4: 45662 | B4: keys-Nermin | C4: =30+25 -> 55 | E4: =E3-C4+D4 -> 1328 | J4: samer Card
A5: 45662 | B5: flasha asansier-Nermin | C5: 50 | E5: =E4-C5+D5 -> 1278 | H5: Various Consumables | I5: =C3+C8+C10+C13+C14+C15+C16+C19+C20+C21+C22+C24 -> 2603 | J5: =C18 -> 2652.35
A6: 45662 | B6: Gas Jan/25 | C6: =18+2 -> 20 | E6: =E5-C6+D6 -> 1258 | H6: Office Supplies | I6: =C4+C5+C9 -> 147
A7: 45663 | B7: Nodust | C7: =113+2 -> 115 | E7: =E6-C7+D7 -> 1143 | H7: Transportation | I7: =C11+C12+C23 -> 112
A8: 45665 | B8: Various Consumables-City Market | C8: =2*48+85*2+5+70 -> 341 | E8: =E7-C8+D8 -> 802 | H8: Gas Jan/25 | I8: =C6 -> 20
A9: 45665 | B9: Note Book - Nagah | C9: 42 | E9: =E8-C9+D9 -> 760
A10: 45666 | B10: Various Consumables-Negmt Heliopolies | C10: =1105.75+0.25 -> 1106 | E10: =E9-C10+D10 -> -346 | H10: Nodust | I10: =C7 -> 115
A11: 45666 | B11: Ebrahim Transportation-Negmt Heliopolies | C11: 28 | E11: =E10-C11+D11 -> -374
A12: 45670 | B12: Ebrahim Transportation-Bank & T2minat | C12: =28*2 -> 56 | E12: =E11-C12+D12 -> -430
A13: 45670 | B13: Coffee-City Market | C13: 75 | E13: =E12-C13+D13 -> -505
A14: 45677 | B14: coffee&Milk -City Market | C14: =75+96 -> 171 | E14: =E13-C14+D14 -> -676
A15: 45680 | B15: Water-City Market | C15: =170+5+5 -> 180 | E15: =E14-C15+D15 -> -856
A16: 45680 | B16: Coffee-City Market | C16: 75 | E16: =E15-C16+D16 -> -931
A17: 45678 | B17: Samer | D17: 2652.35 | E17: =E16-C17+D17 -> 1721.35
A18: 45678 | B18: Various Consumables-Negmt Heliopolies | C18: 2652.35 | E18: =E17-C18+D18 -> -931
A19: 45671 | B19: Milk-City Market | C19: =48*2 -> 96 | E19: =E18-C19+D19 -> -1027
A20: 45676 | B20: Milk-City Market | C20: =48*2 -> 96 | E20: =E19-C20+D20 -> -1123
A21: 45684 | B21: Various Consumables-City Market | C21: =125+5 -> 130 | E21: =E20-C21+D21 -> -1253
A22: 45685 | B22: Water-City Market | C22: 6 | E22: =E21-C22+D22 -> -1259
A23: 45685 | B23: Ebrahim Transportation-Bank | C23: 28 | E23: =E22-C23+D23 -> -1287
A24: 45686 | B24: Various Consumables-City Market | C24: 206 | E24: =E23-C24+D24 -> -1493

Sheet Feb
A1: Date | B1: Item | C1: Debit | D1: Credit | E1: Balance
E2: =Jan!E24 -> -1493
A3: 45690 | B3: Samer | D3: 1000 | E3: =E2-C3+D3 -> -493
A4: 45690 | B4: Doorman Feb-Mar-Apr25 | C4: 1000 | E4: =E3-C4+D4 -> -1493
A5: 45690 | B5: Various Consumables-City Market | C5: 221 | E5: =E4-C5+D5 -> -1714
A6: 45690 | B6: Gas Feb/25 | C6: 17 | E6: =E5-C6+D6 -> -1731 | J6: samer Card
A7: 45690 | B7: Samer | D7: 4000 | E7: =E6-C7+D7 -> 2269 | H7: Various Consumables | I7: =C5+C8+C13+C14+C15+C16+C18+C20+C21+C22+C23+C25+C26+C27 -> 5922
A8: 45691 | B8: Various Consumables-Negmt Heliopolies | C8: =1765.85+0.15 -> 1766 | E8: =E7-C8+D8 -> 503 | H8: Office Supplies | I8: 0
A9: 45691 | B9: Ebrahim Transportation-Negmt Heliopolies | C9: 45 | E9: =E8-C9+D9 -> 458 | H9: Transportation | I9: =C9+C10+C12+C17+C28 -> 213
A10: 45691 | B10: Ebrahim Transportation-Bank | C10: 28 | E10: =E9-C10+D10 -> 430 | H10: Gas Jan/25 | I10: =C6 -> 17
A11: 45691 | B11: Nodust | C11: =113+2 -> 115 | E11: =E10-C11+D11 -> 315 | H11: Plumbing tool | I11: =C24 -> 270
A12: 45692 | B12: Ebrahim Transportation-Bank | C12: 28 | E12: =E11-C12+D12 -> 287 | H12: Nodust | I12: =C11 -> 115
A13: 45692 | B13: Milk-City Market | C13: 96 | E13: =E12-C13+D13 -> 191 | H13: Doorman Feb-Mar-Apr25 | I13: 1000
A14: 45693 | B14: Milk&Water-City Market | C14: =144+85+5 -> 234 | E14: =E13-C14+D14 -> -43 | F14: ebrahim
A15: 45694 | B15: Coffee-City Market | C15: 145 | E15: =E14-C15+D15 -> -188 | F15: nermin
A16: 45694 | B16: Milk-City Market | C16: 96 | E16: =E15-C16+D16 -> -284 | F16: naga7
A17: 45698 | B17: Ebrahim Transportation-T2minat x 2 | C17: =28*2 -> 56 | E17: =E16-C17+D17 -> -340 | F17: ebrahim
A18: 45698 | B18: Milk-City Market | C18: 96 | E18: =E17-C18+D18 -> -436 | F18: mariam
A19: 45699 | B19: Samer | D19: 4000 | E19: =E18-C19+D19 -> 3564
A20: 45699 | B20: Milk&Water-City Market | C20: =85*2+48*2+5 -> 271 | E20: =E19-C20+D20 -> 3293
A21: 45700 | B21: Various Consumables-Negmt Heliopolies | C21: 890 | E21: =E20-C21+D21 -> 2403
A22: 45706 | B22: Coffee-City Market | C22: 150 | E22: =E21-C22+D22 -> 2253
A23: 45706 | B23: Water-City Market | C23: =175+6 -> 181 | E23: =E22-C23+D23 -> 2072
A24: 45706 | B24: Plumbing tool | C24: =200+50+20 -> 270 | E24: =E23-C24+D24 -> 1802
A25: 45711 | B25: Coffee-City Market | C25: 150 | E25: =E24-C25+D25 -> 1652
A26: 45712 | B26: Various Consumables-Negmt Heliopolies | C26: =1450.55+0.45 -> 1451 | E26: =E25-C26+D26 -> 201
A27: 45715 | B27: Water-City Market | C27: =85*2+5 -> 175 | E27: =E26-C27+D27 -> 26
A28: 45715 | B28: Ebrahim Transportation-Bank x 2 | C28: =28*2 -> 56 | E28: =E27-C28+D28 -> -30 | F28: 30mariam

Sheet Mar
A1: Date | B1: Item | C1: Debit | D1: Credit | E1: Balance
E2: =Feb!E28 -> -30
A3: 45719 | B3: Coffee-City Market | C3: 145 | E3: =E2-C3+D3 -> -175
A4: 45719 | B4: lasq | C4: 25 | E4: =E3-C4+D4 -> -200 | J4: samer Card
A5: 45719 | B5: Nodust | C5: =113+2 -> 115 | E5: =E4-C5+D5 -> -315 | F5: بدون فاتورة | H5: Various Consumables | I5: =C3+C7+C8+C9+C12+C13+C14+C15+C16+C17+C18+C23+C25 -> 3754
A6: 45719 | B6: Samer | D6: 4000 | E6: =E5-C6+D6 -> 3685 | H6: Office Supplies | I6: =C4+C10+C21+C22+K18+C19 -> 207
A7: 45721 | B7: Various Consumables-Negmt Heliopolies | C7: =1299.75+0.25 -> 1300 | E7: =E6-C7+D7 -> 2385 | H7: Transportation | I7: =C11+C20+C24 -> 84
A8: 45725 | B8: Milk - City Market | C8: 96 | E8: =E7-C8+D8 -> 2289 | H8: Gas
A9: 45727 | B9: Milk - City Market | C9: 96 | E9: =E8-C9+D9 -> 2193 | H9: Plumbing tool
A10: 45727 | B10: fisha solasia | C10: 35 | E10: =E9-C10+D10 -> 2158 | H10: Nodust | I10: =C5 -> 115
A11: 45727 | B11: Ebrahim Transportation-Bank | C11: 28 | E11: =E10-C11+D11 -> 2130
A12: 45728 | B12: Water-City Market | C12: =85*2+5+150 -> 325 | E12: =E11-C12+D12 -> 1805
A13: 45729 | B13: Milk - City Market | C13: =48*2 -> 96 | E13: =E12-C13+D13 -> 1709
A14: 45729 | B14: Sham3 fltr | C14: 230 | E14: =E13-C14+D14 -> 1479
A15: 45729 | B15: Milk - City Market | C15: 96 | E15: =E14-C15+D15 -> 1383
A16: 45733 | B16: Nescafe- City Market | C16: 275 | E16: =E15-C16+D16 -> 1108
A17: 45736 | B17: milk&Coffee-5l -City Market | C17: =96+75+20 -> 191 | E17: =E16-C17+D17 -> 917
A18: 45740 | B18: Milk&Coffemate -City Market | C18: =96+160 -> 256 | E18: =E17-C18+D18 -> 661
A19: 45740 | B19: flasha asansier-lydia | C19: 50 | E19: =E18-C19+D19 -> 611
A20: 45740 | B20: Ebrahim Transportation-Bank | C20: 28 | E20: =E19-C20+D20 -> 583
A21: 45740 | B21: key-lydia | C21: 30 | E21: =E20-C21+D21 -> 553
A22: 45740 | B22: Notebook&pens | C22: 67 | E22: =E21-C22+D22 -> 486
A23: 45741 | B23: Various Consumables-City Market | C23: 373 | E23: =E22-C23+D23 -> 113
A24: 45741 | B24: Ebrahim Transportation-Bank | C24: 28 | E24: =E23-C24+D24 -> 85
A25: 45743 | B25: Nescafe- City Market | C25: 275 | E25: =E24-C25+D25 -> -190
A26: 45743 | B26: doorman Apr/25 | C26: 50 | E26: =E25-C26+D26 -> -240

Sheet Apr
A1: Date | B1: Item | C1: Debit | D1: Credit | E1: Balance
E2: =Mar!E26 -> -240
A3: 45751 | B3: Milk - City Market | C3: 96 | E3: =E2-C3+D3 -> -336
A4: 45753 | B4: coffee - City Market | C4: 75 | E4: =E3-C4+D4 -> -411 | J4: samer Card
A5: 45754 | B5: Gas Apr/25 | C5: =17+3 -> 20 | E5: =E4-C5+D5 -> -431 | H5: Various Consumables | I5: =C3+C4+C6+C8+C10+C13+C18+C20+C23+C24+C25 -> 5272.5
A6: 45754 | B6: Various Consumables-City Market | C6: =85+96+60+5 -> 246 | E6: =E5-C6+D6 -> -677 | H6: Office Supplies | I6: =C14+C21 -> 80
A7: 45754 | B7: Nodust | C7: =113+2 -> 115 | E7: =E6-C7+D7 -> -792 | H7: Transportation | I7: =C11+C17+C19+C22 -> 184
A8: 45755 | B8: coffee - City Market | C8: 75 | E8: =E7-C8+D8 -> -867 | H8: Gas | I8: =C5 -> 20
A9: 45755 | B9: Samer | D9: 5000 | E9: =E8-C9+D9 -> 4133 | H9: Doorman May-Jun-Jul25 | I9: =C12 -> 1000
A10: 45755 | B10: Various Consumables-Negmt Heliopolies | C10: 2967.5 | E10: =E9-C10+D10 -> 1165.5 | H10: Nodust | I10: =C7 -> 115
A11: 45755 | B11: Ebrahim Transportation-Negmt Heliopolies | C11: =40+14 -> 54 | E11: =E10-C11+D11 -> 1111.5 | H11: Air conditioning cleaning | I11: 1500
A12: 45757 | B12: Doorman May-Jun-Jul25 | C12: 1000 | E12: =E11-C12+D12 -> 111.5
A13: 45761 | B13: Water-City Market | C13: =170+5 -> 175 | E13: =E12-C13+D13 -> -63.5
A14: 45763 | B14: Flasha asansier lydia | C14: 50 | E14: =E13-C14+D14 -> -113.5
A15: 45770 | B15: Samer | D15: 4000 | E15: =E14-C15+D15 -> 3886.5
A16: 45770 | B16: Air conditioning cleaning | C16: 1500 | E16: =E15-C16+D16 -> 2386.5
A17: 45770 | B17: Ebrahim Transportation- Office | C17: 40 | E17: =E16-C17+D17 -> 2346.5
A18: 45770 | B18: Water-City Market | C18: 175 | E18: =E17-C18+D18 -> 2171.5
A19: 45770 | B19: Ebrahim Transportation-Bank | C19: 30 | E19: =E18-C19+D19 -> 2141.5
A20: 45774 | B20: Milk - City Market | C20: =48*2 -> 96 | E20: =E19-C20+D20 -> 2045.5
A21: 45775 | B21: Key-monad | C21: 30 | E21: =E20-C21+D21 -> 2015.5
A22: 45775 | B22: Ebrahim Transportation-Bank(2times) | C22: 60 | E22: =E21-C22+D22 -> 1955.5
A23: 45775 | B23: Milk - City Market | C23: =48*2 -> 96 | E23: =E22-C23+D23 -> 1859.5
A24: 45776 | B24: Milk - City Market | C24: 96 | E24: =E23-C24+D24 -> 1763.5
A25: 45777 | B25: Various Consumables-Negmt Heliopolies | C25: =1173.45+1.55 -> 1175 | E25: =E24-C25+D25 -> 588.5

Sheet May
A1: Date | B1: Item | C1: Debit | D1: Credit | E1: Balance
E2: =[1]Apr!E25 -> 588.5
A3: 45781 | B3: Gas May/25 | C3: =18+2 -> 20 | E3: =E2-C3+D3 -> 568.5
A4: 45782 | B4: Water-City Market | C4: =190+5 -> 195 | E4: =E3-C4+D4 -> 373.5
A5: 45782 | B5: A4 Paper | C5: 160 | E5: =E4-C5+D5 -> 213.5 | J5: samer Card
A6: 45782 | B6: Nodust | C6: =113+2 -> 115 | E6: =E5-C6+D6 -> 98.5 | H6: Various Consumables | I6: =C4+C7+C9+C11+C12+C14+C15+C18+C19+C21 -> 7085
A7: 45788 | B7: milk - City Market | C7: =48*2 -> 96 | E7: =E6-C7+D7 -> 2.5 | H7: Office Supplies | I7: =C5+C13 -> 563
A8: 45788 | B8: Samer | D8: 4000 | E8: =E7-C8+D8 -> 4002.5 | H8: Transportation | I8: =C10+C17+C20+C22 -> 188
A9: 45789 | B9: Various Consumables-Negmt Heliopolies | C9: =2964.35+0.65 -> 2965 | E9: =E8-C9+D9 -> 1037.5 | H9: Gas | I9: =C3 -> 20
A10: 45789 | B10: Ebrahim Transportation-Negmt Heliopolies | C10: 46 | E10: =E9-C10+D10 -> 991.5 | H10: Nodust | I10: =C6 -> 115
A11: 45789 | B11: Water-City Market | C11: 195 | E11: =E10-C11+D11 -> 796.5
A12: 45790 | B12: 2 small Bottle of Water | C12: =2*6 -> 12 | E12: =E11-C12+D12 -> 784.5
A13: 45792 | B13: 9 NoteBook + 5 Pens | C13: =9*42+5*5 -> 403 | E13: =E12-C13+D13 -> 381.5
A14: 45792 | B14: Water-City Market | C14: 195 | E14: =E13-C14+D14 -> 186.5
A15: 45798 | B15: Water&Nescafe City Market | C15: =275+95+5 -> 375 | E15: =E14-C15+D15 -> -188.5
A16: 45798 | B16: Samer | D16: 4000 | E16: =E15-C16+D16 -> 3811.5
A17: 45799 | B17: Ebrahim Transportation-Bank | C17: 30 | E17: =E16-C17+D17 -> 3781.5
A18: 45802 | B18: Water - City Market | C18: 195 | E18: =E17-C18+D18 -> 3586.5
A19: 45803 | B19: Various Consumables-Negmt Heliopolies | C19: 2662 | E19: =E18-C19+D19 -> 924.5
A20: 45803 | B20: Ebrahim Transportation-Negmt Heliopolies | C20: 52 | E20: =E19-C20+D20 -> 872.5
A21: 45803 | B21: Water - City Market | C21: 195 | E21: =E20-C21+D21 -> 677.5
A22: 45803 | B22: Ebrahim Transportation-Bank | C22: =30+30 -> 60 | E22: =E21-C22+D22 -> 617.5

Sheet Jun
A1: Date | B1: Item | C1: Debit | D1: Credit | E1: Balance
E2: =May!E22 -> 617.5
A3: 45809 | B3: Gas Jun/25 | C3: =17+3 -> 20 | E3: =E2-C3+D3 -> 597.5
A4: 45810 | B4: Nodust | C4: =113+2 -> 115 | E4: =E3-C4+D4 -> 482.5
A5: 45811 | B5: Water-City Market | C5: 195 | E5: =E4-C5+D5 -> 287.5 | J5: samer Card
A6: 45812 | B6: Cash | D6: 5000 | E6: =E5-C6+D6 -> 5287.5 | H6: Various Consumables | I6: =C5+C7+C12+C18+C20+C21+C23+C25 -> 7677.5
A7: 45818 | B7: Various Consumables-Negmt Heliopolies | C7: 2901 | E7: =E6-C7+D7 -> 2386.5 | H7: Office Supplies | I7: =C16 -> 70
A8: 45818 | B8: Ebrahim Transportation-Negmt Heliopolies | C8: 55 | E8: =E7-C8+D8 -> 2331.5 | H8: Transportation | I8: =C8+C9+C10+C13+C14+C17+C22+C26+C27 -> 625
A9: 45812 | B9: Ebrahim Transportation-Bank | C9: 30 | E9: =E8-C9+D9 -> 2301.5 | H9: Gas | I9: =C3 -> 20
A10: 45818 | B10: Ebrahim Transportation-Bank | C10: 90 | E10: =E9-C10+D10 -> 2211.5 | H10: Nodust | I10: =C4+C28 -> 230
A11: 45812 | B11: Electricity | C11: 414 | E11: =E10-C11+D11 -> 1797.5 | H11: plumbing Fees | I11: =C19 -> 350
A12: 45818 | B12: Various Consumables-City Market | C12: =95+120+165+140 -> 520 | E12: =E11-C12+D12 -> 1277.5 | H12: Electricity | I12: 414
A13: 45819 | B13: Ebrahim Transportation-SSE | C13: =45+85+85 -> 215 | E13: =E12-C13+D13 -> 1062.5
A14: 45819 | B14: Ebrahim Transportation-Bank | C14: 30 | E14: =E13-C14+D14 -> 1032.5
A15: 45819 | B15: Cash | D15: 495 | E15: =E14-C15+D15 -> 1527.5
A16: 45823 | B16: Cups | C16: 70 | E16: =E15-C16+D16 -> 1457.5
A17: 45823 | B17: Ebrahim Transportation-Samer | C17: 95 | E17: =E16-C17+D17 -> 1362.5
A18: 45824 | B18: Water-City Market | C18: 195 | E18: =E17-C18+D18 -> 1167.5
A19: 45824 | B19: plumbing Fees | C19: 350 | E19: =E18-C19+D19 -> 817.5
A20: 45827 | B20: Water-City Market | C20: 195 | E20: =E19-C20+D20 -> 622.5
A21: 45827 | B21: Various Consumables-City Market | C21: 165 | E21: =E20-C21+D21 -> 457.5
A22: 45830 | B22: Ebrahim Transportation-Bank | C22: 30 | E22: =E21-C22+D22 -> 427.5
A23: 45833 | B23: Water-City Market | C23: 195 | E23: =E22-C23+D23 -> 232.5
A24: 45838 | B24: Cash | D24: =7576.91+0.09 -> 7577 | E24: =E23-C24+D24 -> 7809.5
A25: 45838 | B25: Various Consumables-Negmt Heliopolies | C25: 3311.5 | E25: =E24-C25+D25 -> 4498
A26: 45838 | B26: Ebrahim Transportation-Negmt Heliopolies | C26: 50 | E26: =E25-C26+D26 -> 4448
A27: 45838 | B27: Ebrahim Transportation-Bank | C27: 30 | E27: =E26-C27+D27 -> 4418
A28: 45838 | B28: Nodust | C28: =113+2 -> 115 | E28: =E27-C28+D28 -> 4303

Sheet Jul
A1: Date | B1: Item | C1: Debit | D1: Credit | E1: Balance
E2: =Jun!E28 -> 4303
A3: 45839 | B3: Water-City Market | C3: 195 | E3: =E2-C3+D3 -> 4108
A4: 45840 | B4: Ebrahim Transportation-Cheers & Bank | C4: 30 | E4: =E3-C4+D4 -> 4078
A5: 45844 | B5: Ebrahim Transportation-Bank | C5: 30 | E5: =E4-C5+D5 -> 4048
A6: 45844 | B6: Cash | D6: 6000 | E6: =E5-C6+D6 -> 10048 | J6: samer Card
A7: 45846 | B7: fisha MK | C7: 35 | E7: =E6-C7+D7 -> 10013 | H7: Various Consumables | I7: =C3+C9+C10+C14+C15+C17+C22 -> 4073
A8: 45848 | B8: Gas Jul/25 | C8: =18+2 -> 20 | E8: =E7-C8+D8 -> 9993 | H8: Office Supplies | I8: =C7 -> 35
A9: 45848 | B9: Water-City Market | C9: =190+5 -> 195 | E9: =E8-C9+D9 -> 9798 | H9: Transportation | I9: =C4+C5+C16+C20 -> 135
A10: 45854 | B10: Water-City Market | C10: 195 | E10: =E9-C10+D10 -> 9603 | H10: Gas | I10: =C8 -> 20
A11: 45855 | B11: syant tkiefat elshrka | C11: =350+550 -> 900 | E11: =E10-C11+D11 -> 8703 | H11: Nodust | I11: =C21 -> 120
A12: 45857 | B12: Electricity | C12: 500 | E12: =E11-C12+D12 -> 8203 | H12: Carpenter Fees | I12: =C13 -> 455
A13: 45857 | B13: Msn3it Tsli7 shobak el7mam | C13: 455 | E13: =E12-C13+D13 -> 7748 | H13: Electricity | I13: =C12 -> 500
A14: 45858 | B14: Water&Milk-City Market | C14: =48+95+5 -> 148 | E14: =E13-C14+D14 -> 7600 | H14: Electric Tools | I14: =C18 -> 245
A15: 45859 | B15: Various Consumables-Negmt Heliopolies | C15: 2945 | E15: =E14-C15+D15 -> 4655 | H15: doorman Aug&Sep&Oct/25 | I15: =C19 -> 1100
A16: 45859 | B16: Ebrahim Transportation-Negmt Heliopolies | C16: 45 | E16: =E15-C16+D16 -> 4610 | H16: syant tkiefat elshrka | I16: 900
A17: 45865 | B17: Water City Market | C17: 195 | E17: =E16-C17+D17 -> 4415
A18: 45865 | B18: Electric Tools | C18: 245 | E18: =E17-C18+D18 -> 4170
A19: 45865 | B19: doorman Aug&Sep&Oct/25 | C19: 1100 | E19: =E18-C19+D19 -> 3070
A20: 45866 | B20: Ebrahim Transportation-Bank | C20: 30 | E20: =E19-C20+D20 -> 3040
A21: 45866 | B21: Nodust | C21: =113+7 -> 120 | E21: =E20-C21+D21 -> 2920
A22: 45868 | B22: Water City Market | C22: 200 | E22: =E21-C22+D22 -> 2720

Sheet Aug
A1: Date | B1: Item | C1: Debit | D1: Credit | E1: Balance
E2: =Jul!E22 -> 2720
A3: 45872 | B3: Electricity | C3: 517 | E3: =E2-C3+D3 -> 2203
A4: 45872 | B4: Milk-City Market | C4: 96 | E4: =E3-C4+D4 -> 2107
A5: 45872 | B5: Gas | C5: 20 | E5: =E4-C5+D5 -> 2087
A6: 45873 | B6: Milk-City Market | C6: 96 | E6: =E5-C6+D6 -> 1991
A7: 45874 | B7: Various Consumables-Negmt Heliopolies | C7: =1644+1 -> 1645 | E7: =E6-C7+D7 -> 346 | H7: Various Consumables | I7: =C4+C6+C7+C9+C11+C15+C18+C20+C21+C26+C30+C33 -> 5479
A8: 45874 | B8: Ebrahim Transportation-Negmt Heliopolies | C8: 55 | E8: =E7-C8+D8 -> 291 | H8: Office Supplies | I8: =C31+C34 -> 170
A9: 45874 | B9: Water City Market | C9: 195 | E9: =E8-C9+D9 -> 96 | H9: Transportation | I9: =C8+C12+C16+C17+C19+C23+C24+C25+C28+C32 -> 745
A10: 45876 | B10: Samer | D10: 1000 | E10: =E9-C10+D10 -> 1096 | H10: Gas | I10: =C5 -> 20
A11: 45876 | B11: Coffee mate -City Market | C11: 165 | E11: =E10-C11+D11 -> 931 | H11: Nodust | I11: =C29 -> 115
A12: 45876 | B12: Ebrahim Transportation-Bank-samer | C12: 250 | E12: =E11-C12+D12 -> 681 | H12: Plumping Fees | I12: =C27 -> 100
A13: 45876 | B13: Electricity | C13: 515 | E13: =E12-C13+D13 -> 166 | H13: Electricity | I13: =C3+C13 -> 1032
A14: 45880 | B14: Cash | D14: 5000 | E14: =E13-C14+D14 -> 5166 | H14: Cleening Tools | I14: =C22 -> 130
A15: 45880 | B15: Water City Market | C15: 195 | E15: =E14-C15+D15 -> 4971
A16: 45880 | B16: Ebrahim Transportation-Bank | C16: 30 | E16: =E15-C16+D16 -> 4941
A17: 45880 | B17: Ebrahim& Nermeen Transportation-makram | C17: 200 | E17: =E16-C17+D17 -> 4741
A18: 45881 | B18: Various Consumables-Negmt Heliopolies | C18: 2291 | E18: =E17-C18+D18 -> 2450
A19: 45881 | B19: Ebrahim Transportation-Negmt Heliopolies | C19: 60 | E19: =E18-C19+D19 -> 2390
A20: 45882 | B20: Msharib l 3omal trkib eltakieef | C20: 45 | E20: =E19-C20+D20 -> 2345
A21: 45883 | B21: Water City Market | C21: 195 | E21: =E20-C21+D21 -> 2150
A22: 45883 | B22: Cleening Tools-Ebrahim | C22: =2*40+2*25 -> 130 | E22: =E21-C22+D22 -> 2020
A23: 45883 | B23: Ebrahim Transportation-Bank | C23: 30 | E23: =E22-C23+D23 -> 1990
A24: 45886 | B24: Ebrahim Transportation-Bank | C24: 30 | E24: =E23-C24+D24 -> 1960
A25: 45886 | B25: Ebrahim Transportation-B.Tech | C25: 30 | E25: =E24-C25+D25 -> 1930
A26: 45888 | B26: Water & Sugar City Market | C26: =190+70+5 -> 265 | E26: =E25-C26+D26 -> 1665
A27: 45888 | B27: Plumping Fees-tsli7 sifon | C27: 100 | E27: =E26-C27+D27 -> 1565
A28: 45890 | B28: Ebrahim Transportation-Bank | C28: 30 | E28: =E27-C28+D28 -> 1535
A29: 45894 | B29: Nodust | C29: 115 | E29: =E28-C29+D29 -> 1420
A30: 45894 | B30: Water City Market | C30: 195 | E30: =E29-C30+D30 -> 1225
A31: 45896 | B31: Moshtrk - 7azem | C31: 130 | E31: =E30-C31+D31 -> 1095
A32: 45896 | B32: Ebrahim Transportation-Bank | C32: 30 | E32: =E31-C32+D32 -> 1065
A33: 45897 | B33: Milk-City Market | C33: 96 | E33: =E32-C33+D33 -> 969
A34: 45897 | B34: Fisha A16 - ibrahim | C34: 40 | E34: =E33-C34+D34 -> 929

Sheet Sep
A1: Date | B1: Item | C1: Debit | D1: Credit | E1: Balance
E2: =Aug!E34 -> 929
A3: 45901 | B3: Various Consumables-City Market | C3: =231+48+96 -> 375 | E3: =E2-C3+D3 -> 554
A4: 45901 | B4: Electricity | C4: 517 | E4: =E3-C4+D4 -> 37
A5: 45901 | B5: Gas | C5: 20 | E5: =E4-C5+D5 -> 17
A6: 45901 | B6: Samer | D6: 4000 | E6: =E5-C6+D6 -> 4017
A7: 45902 | B7: Various Consumables-Negmt Heliopolies | C7: 3070 | E7: =E6-C7+D7 -> 947 | H7: Various Consumables | I7: =C3+C7+C9+C11+C12+C13+C15+C16+C19+C21+C24+C27+C29+C30 -> 10010
A8: 45902 | B8: Ebrahim Transportation-Negmt Heliopolies | C8: 50 | E8: =E7-C8+D8 -> 897 | H8: Office Supplies | I8: =C25 -> 286
A9: 45907 | B9: Water City Market | C9: 195 | E9: =E8-C9+D9 -> 702 | H9: Transportation | I9: =C8+C20+C22+C26+C31 -> 285
A10: 45907 | B10: Electricity - mina | C10: 517 | E10: =E9-C10+D10 -> 185 | H10: Gas | I10: =C5 -> 20
A11: 45907 | B11: Juice For Client | C11: 125 | E11: =E10-C11+D11 -> 60 | H11: Nodust | I11: =C23 -> 115
A12: 45911 | B12: Water City Market | C12: 195 | E12: =E11-C12+D12 -> -135
A13: 45915 | B13: Milk-Sugar-City Market | C13: 166 | E13: =E12-C13+D13 -> -301 | H13: Electricity | I13: =C10+C4+C14 -> 1549
A14: 45917 | B14: Electricity | C14: 515 | E14: =E13-C14+D14 -> -816 | H14: doorman Nov/25 | I14: 350
A15: 45917 | B15: Milk-City Market | C15: 192 | E15: =E14-C15+D15 -> -1008
A16: 45917 | B16: Water City Market | C16: 195 | E16: =E15-C16+D16 -> -1203
A17: 45917 | B17: Samer | D17: 4000 | E17: =E16-C17+D17 -> 2797
A18: 45917 | B18: doorman Nov/25 | C18: 350 | E18: =E17-C18+D18 -> 2447
A19: 45918 | B19: Various Consumables-Negmt Heliopolies | C19: 2555 | E19: =E18-C19+D19 -> -108 | H19: =215+18+200 -> 433 | I19: Mariam
A20: 45918 | B20: Ebrahim Transportation-Negmt Heliopolies | C20: 60 | E20: =E19-C20+D20 -> -168 | H20: =90+30 -> 120 | I20: Ebrahim
A21: 45921 | B21: Water City Market | C21: =3*6 -> 18 | E21: =E20-C21+D21 -> -186 | H21: =115+195+425 -> 735 | I21: Nagah
A22: 45922 | B22: Ebrahim Transportation -Bank-3 times | C22: =30*3 -> 90 | E22: =E21-C22+D22 -> -276 | H22: 86 | I22: nermin
A23: 45922 | B23: Nodust | C23: 115 | E23: =E22-C23+D23 -> -391
A24: 45923 | B24: Water City Market | C24: 195 | E24: =E23-C24+D24 -> -586
A25: 45923 | B25: Office Supplies | C25: =36+75+25+150 -> 286 | E25: =E24-C25+D25 -> -872
A26: 45923 | B26: Ebrahim Transportation - T2minat | C26: 30 | E26: =E25-C26+D26 -> -902
A27: 45928 | B27: Various Consumables-City Market | C27: =48*3+280+1 -> 425 | E27: =E26-C27+D27 -> -1327
A28: 45929 | B28: Samer | D28: 4000 | E28: =E27-C28+D28 -> 2673
A29: 45929 | B29: Various Consumables-City Market | C29: =96+190+5 -> 291 | E29: =E28-C29+D29 -> 2382
A30: 45930 | B30: Various Consumables-Negmt Heliopolies | C30: 2013 | E30: =E29-C30+D30 -> 369
A31: 45930 | B31: Ebrahim Transportation-Negmt Heliopolies | C31: 55 | E31: =E30-C31+D31 -> 314

Sheet Oct
A1: Date | B1: Item | C1: Debit | D1: Credit | E1: Balance
E2: =Sep!E31 -> 314
A3: 45931 | B3: Gas | C3: 20 | E3: =E2-C3+D3 -> 294
A4: 45935 | B4: Water City Market | C4: 195 | E4: =E3-C4+D4 -> 99 | I4: =-30+144+118-12 -> 220 | J4: مريم
A5: 45935 | B5: Ebrahim Transportation -Bank | C5: 30 | E5: =E4-C5+D5 -> 69 | I5: =12+26 -> 38 | J5: ابراهيم
A6: 45936 | B6: Ebrahim Transportation -Bank-t2minat | C6: 60 | E6: =E5-C6+D6 -> 9 | I6: =400+400+600 -> 1400 | J6: نجاح
A7: 45936 | B7: 7gara | C7: 70 | E7: =E6-C7+D7 -> -61 | F7: مريم | I7: 0 | J7: Shady
A8: 45937 | B8: Ebrahim Transportation & tsweer -t2minat | C8: 40 | E8: =E7-C8+D8 -> -101 | F8: ابراهيم
A9: 45944 | B9: Water City Market | C9: 195 | E9: =E8-C9+D9 -> -296 | F9: نجاح
A10: 45950 | B10: 4milk-City Market | C10: 192 | E10: =E9-C10+D10 -> -488 | H10: Various Consumables | I10: =C4+C9+C10+C14+C15+C16+C18 -> 1939
A11: 45950 | B11: Nodust | C11: 115 | E11: =E10-C11+D11 -> -603 | H11: Office Supplies | I11: =C7 -> 70
A12: 45950 | B12: Samer | D12: 4000 | E12: =E11-C12+D12 -> 3397 | H12: Transportation | I12: =C5+C6+C8+C17 -> 202
A13: 45950 | B13: Building Maintenance For 6months(Nov/25:Apr/26) | C13: 3000 | E13: =E12-C13+D13 -> 397 | H13: Gas | I13: =C3 -> 20
A14: 45952 | B14: Various Consumables-City Market | C14: 407 | E14: =E13-C14+D14 -> -10 | H14: Nodust | I14: =C11 -> 115
A15: 45953 | B15: Various Consumables-City Market | C15: 400 | E15: =E14-C15+D15 -> -410
A16: 45957 | B16: Various Consumables-City Market | C16: 406 | E16: =E15-C16+D16 -> -816
A17: 45958 | B17: Ebrahim Transportation-Bank (2 times) | C17: 72 | E17: =E16-C17+D17 -> -888
A18: 45960 | B18: 3 milk-City Market | C18: 144 | E18: =E17-C18+D18 -> -1032

Sheet Nov
A1: Date | B1: Item | C1: Debit | D1: Credit | E1: Balance
E2: =Oct!E18 -> -1032
A3: 45963 | B3: Various Consumables-City Market | C3: =130+190+96+55+150+5 -> 626 | E3: =E2-C3+D3 -> -1658
A4: 45963 | B4: Ebrahim Transportation-Doki(samer) | C4: 85 | E4: =E3-C4+D4 -> -1743
A5: 45964 | B5: Gas | C5: 20 | E5: =E4-C5+D5 -> -1763
A6: 45965 | B6: Samer | D6: 5000 | E6: =E5-C6+D6 -> 3237
A7: 45965 | B7: Various Consumables-Negmt Heliopolies | C7: 3017 | E7: =E6-C7+D7 -> 220
A8: 45965 | B8: Ebrahim Transportation-Negmt Heliopolies | C8: 70 | E8: =E7-C8+D8 -> 150
A9: 45965 | B9: bottel of water | C9: 6 | E9: =E8-C9+D9 -> 144
A10: 45970 | B10: Ebrahim Transportation-t2minat | C10: =18*2 -> 36 | E10: =E9-C10+D10 -> 108 | H10: Various Consumables | I10: =C3+C7+C9+C11+C14+C19+C20+C22+C24+C25 -> 6953
A11: 45970 | B11: Water City Market | C11: 195 | E11: =E10-C11+D11 -> -87 | H11: Office Supplies | I11: =C12 -> 85
A12: 45972 | B12: moshtark-nermin | C12: 85 | E12: =E11-C12+D12 -> -172 | H12: Transportation | I12: =C4+C8+C10+C13+C17+C18+C21 -> 354
A13: 45973 | B13: Ebrahim Transportation-Bank | C13: 36 | E13: =E12-C13+D13 -> -208 | H13: Gas | I13: =C5 -> 20
A14: 45974 | B14: Nescafe | C14: 490 | E14: =E13-C14+D14 -> -698 | H14: Nodust | I14: =C23 -> 115
A15: 45974 | B15: Samer | D15: 4000 | E15: =E14-C15+D15 -> 3302 | H15: doorman dec/25 | I15: =C16 -> 350
A16: 45974 | B16: doorman Dec/25 | C16: 350 | E16: =E15-C16+D16 -> 2952
A17: 45974 | B17: Ebrahim Transportation-Bank | C17: 36 | E17: =E16-C17+D17 -> 2916
A18: 45977 | B18: Ebrahim Transportation-Bank | C18: 36 | E18: =E17-C18+D18 -> 2880
A19: 45978 | B19: Water City Market | C19: 195 | E19: =E18-C19+D19 -> 2685
A20: 45980 | B20: Various Consumables-Negmt Heliopolies | C20: 2103 | E20: =E19-C20+D20 -> 582
A21: 45980 | B21: Ebrahim Transportation-Negmt Heliopolies | C21: 55 | E21: =E20-C21+D21 -> 527
A22: 45980 | B22: bottel of water | C22: 6 | E22: =E21-C22+D22 -> 521
A23: 45985 | B23: Nodust | C23: 115 | E23: =E22-C23+D23 -> 406
A24: 45986 | B24: Water City Market | C24: 195 | E24: =E23-C24+D24 -> 211
A25: 45986 | B25: Coffee mate | C25: 120 | E25: =E24-C25+D25 -> 91

Sheet Dec
A1: Date | B1: Item | C1: Debit | D1: Credit | E1: Balance
E2: =Nov!E25 -> 91
A3: 45994 | B3: Samer | D3: 4000 | E3: =E2-C3+D3 -> 4091
A4: 45994 | B4: Various Consumables-Negmt Heliopolies | C4: 3294 | E4: =E3-C4+D4 -> 797
A5: 45994 | B5: Ebrahim Transportation-Negmt Heliopolies | C5: 55 | E5: =E4-C5+D5 -> 742
A6: 45994 | B6: Water City Market | C6: 195 | E6: =E5-C6+D6 -> 547
A7: 45994 | B7: Zina christmas | C7: 120 | E7: =E6-C7+D7 -> 427 | H7: Various Consumables | I7: =C4+C6+C12+C13+C14+C17+C19+C20 -> 7105
A8: 45998 | B8: Zina christmas | C8: 200 | E8: =E7-C8+D8 -> 227 | H8: Office Supplies | I8: =C7+C8+C9+C18 -> 650
A9: 45998 | B9: Basket | C9: 30 | E9: =E8-C9+D9 -> 197 | H9: Transportation | I9: =C5+C10+C11 -> 127
A10: 45999 | B10: Ebrahim Transportation-Bank | C10: 36 | E10: =E9-C10+D10 -> 161 | H10: Gas
A11: 46000 | B11: Ebrahim Transportation-Bank | C11: 36 | E11: =E10-C11+D11 -> 125 | H11: Nodust | I11: =C15 -> 115
A12: 46005 | B12: Water City Market | C12: 95 | E12: =E11-C12+D12 -> 30
A13: 46005 | B13: Coffee mate | C13: 157 | E13: =E12-C13+D13 -> -127
A14: 46009 | B14: Water City Market | C14: 195 | E14: =E13-C14+D14 -> -322
A15: 46013 | B15: Nodust | C15: 115 | E15: =E14-C15+D15 -> -437
A16: 46019 | B16: Samer | D16: 4000 | E16: =E15-C16+D16 -> 3563
A17: 46019 | B17: Various Consumables-Carfour | C17: =2842.8+7.2 -> 2850 | E17: =E16-C17+D17 -> 713
A18: 46019 | B18: A4 Paper-2 package | C18: 300 | E18: =E17-C18+D18 -> 413
A19: 46020 | B19: Coffee mate | C19: 79 | E19: =E18-C19+D19 -> 334
A20: 46020 | B20: Various Consumables | C20: =110+35+35+60 -> 240 | E20: =E19-C20+D20 -> 94

Sheet Income Pivot
B2: Sum of Absolute Total | C2: Column Labels
B3: Row Labels | C3: Grand Total
B4: Grand Total

Sheet Payroll Pivot
B2: Sum of Absolute Total | C2: Column Labels
C3: Payroll | F3: Payroll Total | G3: Grand Total
B4: Row Labels | C4: 1 | D4: 3 | E4: 4
B5: Feb | C5: 75700 | D5: 50600 | E5: 29850 | F5: 156150 | G5: 156150
B6: Mar | C6: 79500 | D6: 50600 | E6: 29850 | F6: 159950 | G6: 159950
B7: Apr | C7: 149300 | D7: 101200 | E7: 52300 | F7: 302800 | G7: 302800
B8: Jun | C8: 84200 | D8: 43600 | E8: 22450 | F8: 150250 | G8: 150250
B9: Jul | C9: 88800 | D9: 36600 | E9: 23250 | F9: 148650 | G9: 148650
B10: Aug | C10: 78300 | D10: 38100 | E10: 23250 | F10: 139650 | G10: 139650
B11: Sep | C11: 79300 | D11: 36600 | E11: 23250 | F11: 139150 | G11: 139150
B12: Oct | C12: 74600 | D12: 36900 | E12: 18500 | F12: 130000 | G12: 130000
B13: Grand Total | C13: 709700 | D13: 394200 | E13: 222700 | F13: 1326600 | G13: 1326600

Sheet Expenses Pivot
B2: Sum of Absolute Total | C2: Column Labels
B3: Row Labels | C3: CapEx | D3: Cost of Sales | E3: OpEx | F3: Payroll | G3: Tax | H3: Grand Total
B4: Jan | C4: 2347 | D4: 1309.3549 | E4: 27913.906 | G4: 19160.12 | H4: 50730.381
B5: Feb | C5: 2347 | D5: 859.23 | E5: 31992.881 | F5: 156150 | G5: 60760.19 | H5: 252109.3
B6: Mar | C6: 2347 | D6: 6945.2003 | E6: 27658.011 | F6: 159950 | G6: 22077.7 | H6: 218977.91
B7: Apr | C7: 2347 | D7: 246.17 | E7: 25031.176 | F7: 302800 | G7: 26442 | H7: 356866.35
B8: May | C8: 2732 | D8: 7489.8785 | E8: 28286.288 | G8: 11390.69 | H8: 49898.857
B9: Jun | C9: 2347 | D9: 588.69592 | E9: 29282.313 | F9: 150250 | G9: 69631.53 | H9: 252099.54
B10: Jul | D10: 2217.8444 | E10: 24025.185 | F10: 148650 | G10: 44746.38 | H10: 219639.41
B11: Aug | D11: 1043.86 | E11: 23174.399 | F11: 139650 | G11: 15493 | H11: 179361.26
B12: Sep | D12: 246.17 | E12: 24006.79 | F12: 139150 | G12: 11088.46 | H12: 174491.42
B13: Oct | E13: 44936.4 | F13: 130000 | G13: 29544.24 | H13: 204480.64
B14: Nov | E14: 18371.3 | H14: 18371.3
B15: Dec | E15: 11390.65 | H15: 11390.65
B16: Grand Total | C16: 14467 | D16: 20946.404 | E16: 316069.3 | F16: 1326600 | G16: 310334.31 | H16: 1988417

Sheet OpEx Pivot
B2: Sum of Absolute Total | C2: Column Labels
C3: OpEx | R3: OpEx Total | S3: Grand Total
C4: Bank Charges | D4: Bills | E4: Consumables | F4: Internet | G4: Office Supplies | H4: Other | I4: Other Total | J4: Rent | K4: Services | L4: Subscriptions | M4: Transportation | N4: Utilities | O4: (blank) | Q4: (blank) Total
B5: Row Labels | H5: Office | O5: (blank) | P5: Phone mail
B6: Jan | C6: 373.6161 | D6: 1800 | E6: 2599 | J6: 14641 | K6: 1200 | L6: 5222.6697 | M6: 130 | N6: 1933.06 | O6: 14.56 | Q6: 14.56 | R6: 27913.906 | S6: 27913.906
B7: Feb | C7: 987.56 | E7: 3860 | F7: 513.2108 | G7: 100 | H7: 4230 | I7: 4230 | J7: 14641 | K7: 350 | L7: 5076.6098 | M7: 255 | N7: 1979.5 | R7: 31992.881 | S7: 31992.881
B8: Mar | C8: 810.423 | E8: 2841 | F8: 1353.21 | J8: 14641 | K8: 350 | L8: 6350.0483 | M8: 350 | N8: 962.33 | R8: 27658.011 | S8: 27658.011
B9: Apr | C9: 251.52 | E9: 672 | F9: 2503 | J9: 14641 | K9: 350 | L9: 6178.6561 | M9: 435 | R9: 25031.176 | S9: 25031.176
B10: May | C10: 649.22 | E10: 2753 | F10: 1100 | H10: 460 | I10: 460 | J10: 14641 | K10: 350 | L10: 6967.4988 | M10: 285 | N10: 889.81 | P10: 190.75965 | Q10: 190.75965 | R10: 28286.288 | S10: 28286.288
B11: Jun | C11: 870.57 | E11: 2160 | F11: 815.1 | J11: 14641 | K11: 880 | L11: 7010.2333 | M11: 620 | N11: 2285.41 | R11: 29282.313 | S11: 29282.313
B12: Jul | C12: 426.1 | E12: 1287.5 | F12: 1140 | J12: 14641 | K12: 350 | L12: 5523.3956 | M12: 468.5 | P12: 188.68944 | Q12: 188.68944 | R12: 24025.185 | S12: 24025.185
B13: Aug | C13: 370.78 | D13: 1800 | E13: 2158.84 | F13: 2117.27 | J13: 14685.28 | K13: 1000 | L13: 788.22922 | M13: 254 | R13: 23174.399 | S13: 23174.399
B14: Sep | C14: 444.21 | E14: 2488 | F14: 1140 | J14: 14685.28 | K14: 350 | L14: 0 | M14: 235 | N14: 4664.3 | R14: 24006.79 | S14: 24006.79
B15: Oct | C15: 299.11996 | E15: 2086 | J15: 14685.28 | K15: 27150 | M15: 416 | N15: 300 | R15: 44936.4 | S15: 44936.4
B16: Nov | C16: 197.02 | E16: 1929 | F16: 1140 | J16: 14685.28 | K16: 350 | M16: 70 | R16: 18371.3 | S16: 18371.3
B17: Dec | K17: 6000 | N17: 5390.65 | R17: 11390.65 | S17: 11390.65
B18: Grand Total | C18: 5680.1391 | D18: 3600 | E18: 24834.34 | F18: 11821.791 | G18: 100 | H18: 4690 | I18: 4690 | J18: 161228.12 | K18: 38680 | L18: 43117.341 | M18: 3518.5 | N18: 18405.06 | O18: 14.56 | P18: 379.4491 | Q18: 394.0091 | R18: 316069.3 | S18: 316069.3

Sheet CoS Pivot
B2: Sum of Absolute Total | C2: Column Labels
C3: Cost of Sales | G3: Cost of Sales Total | H3: Grand Total
C4: Ads Spend | D4: Hosting Spend | E4: Plugins | F4: Domains Spend
B5: Row Labels
B6: Jan | C6: 1018.04 | F6: 291.3149 | G6: 1309.3549 | H6: 1309.3549
B7: Feb | C7: 246.17 | D7: 613.06 | G7: 859.23 | H7: 859.23
B8: Mar | C8: 3056.17 | E8: 3234.14 | F8: 654.8903 | G8: 6945.2003 | H8: 6945.2003
B9: Apr | C9: 246.17 | G9: 246.17 | H9: 246.17
B10: May | C10: 3056.17 | D10: 1021.0593 | F10: 3412.6492 | G10: 7489.8785 | H10: 7489.8785
B11: Jun | C11: 246.17 | D11: 342.52592 | G11: 588.69592 | H11: 588.69592
B12: Jul | C12: 246.17 | D12: 335.57876 | F12: 1636.0956 | G12: 2217.8444 | H12: 2217.8444
B13: Aug | C13: 246.17 | D13: 0 | F13: 797.69 | G13: 1043.86 | H13: 1043.86
B14: Sep | C14: 246.17 | G14: 246.17 | H14: 246.17
B15: Grand Total | C15: 8607.4 | D15: 2312.224 | E15: 3234.14 | F15: 6792.6401 | G15: 20946.404 | H15: 20946.404

Sheet Tax Pivot
B2: Sum of Absolute Total | C2: Column Labels
C3: Tax | G3: Tax Total | H3: Grand Total
B4: Row Labels | C4: Deduction Tax | D4: VAT | E4: Payroll Tax | F4: Social Insurance
B5: Jan | D5: 19160.12 | G5: 19160.12 | H5: 19160.12
B6: Feb | C6: 3310 | D6: 57450.19 | G6: 60760.19 | H6: 60760.19
B7: Mar | D7: 22077.7 | G7: 22077.7 | H7: 22077.7
B8: Apr | D8: 9310 | E8: 17132 | G8: 26442 | H8: 26442
B9: May | D9: 11390.69 | G9: 11390.69 | H9: 11390.69
B10: Jun | D10: 12420.06 | F10: 57211.47 | G10: 69631.53 | H10: 69631.53
B11: Jul | D11: 16007.34 | E11: 28739.04 | G11: 44746.38 | H11: 44746.38
B12: Aug | D12: 15493 | G12: 15493 | H12: 15493
B13: Sep | D13: 11088.46 | G13: 11088.46 | H13: 11088.46
B14: Oct | E14: 29544.24 | G14: 29544.24 | H14: 29544.24
B15: Grand Total | C15: 3310 | D15: 174397.56 | E15: 75415.28 | F15: 57211.47 | G15: 310334.31 | H15: 310334.31

Sheet Ads Pivot
B2: Sum of Absolute Total | C2: Column Labels
B3: Row Labels | C3: Ads Spend
B4: Jan | C4: 1018.04
B5: Feb | C5: 246.17
B6: Mar | C6: 3056.17
B7: Apr | C7: 246.17
B8: May | C8: 3056.17
B9: Jun | C9: 246.17
B10: Jul | C10: 246.17
B11: Aug | C11: 246.17
B12: Sep | C12: 246.17
B13: Grand Total | C13: 8607.4

Sheet Hosting Pivot
B2: Sum of Absolute Total | C2: Column Labels
B3: Row Labels | C3: Hosting Spend | D3: Domains Spend
B4: Jan | D4: 291.3149
B5: Feb | C5: 613.06
B6: Mar | D6: 654.8903
B7: May | C7: 1021.0593 | D7: 3412.6492
B8: Jun | C8: 342.52592
B9: Jul | C9: 335.57876 | D9: 1636.0956
B10: Aug | C10: 0 | D10: 797.69
B11: Grand Total | C11: 2312.224 | D11: 6792.6401

Sheet Customers Count Pivot
B2: Count of Absolute Total | C2: Column Labels
B4: Row Labels
A5: 1
A6: 2
A7: 3
A8: 4
A9: 5
A10: 6
A11: 7
A12: 8
A13: 9
A14: 10
A15: 11
A16: 12
A18: =A5 -> 1
A19: =A6 -> 2
A20: =A7 -> 3
A21: =A8 -> 4
A22: =A9 -> 5
A23: =A10 -> 6
A24: =A11 -> 7
A25: =A12 -> 8 | B25: =B12 -> 0 | C25: =COUNT(C12:AY12) -> 0
A26: =A13 -> 9 | B26: =B13 -> 0 | C26: =COUNT(C13:AY13) -> 0
A27: =A14 -> 10 | B27: =B14 -> 0 | C27: =COUNT(C14:AY14) -> 0
A28: =A15 -> 11 | B28: =B15 -> 0 | C28: =COUNT(C15:AY15) -> 0
A29: =A16 -> 12 | B29: =B16 -> 0 | C29: =COUNT(C16:AY16) -> 0

Sheet VAT Pivot
B2: Sum of Absolute Total | C2: Column Labels
B3: Row Labels | C3: VAT Spend
B4: Jan | C4: 19160.12
B5: Feb | C5: 57450.19
B6: Mar | C6: 22077.7
B7: Apr | C7: 9310
B8: May | C8: 11390.69
B9: Jun | C9: 12420.06
B10: Jul | C10: 16007.34
B11: Aug | C11: 15493
B12: Sep | C12: 11088.46

Sheet Categories
B2: Aura Systems
B3: Category List
B5: Type | C5: Category | D5: Description | E5: Sub Categories
B6: CapEx | C6: Air Conditioning
B7: CapEx | C7: Appliances
B8: CapEx | C8: Bathroom Supplies
B9: CapEx | C9: Business Cards
B10: CapEx | C10: Chairs
B11: CapEx | C11: Desk Surfaces
B12: CapEx | C12: Desks
B13: CapEx | C13: Domain
B14: CapEx | C14: Electric Supplies
B15: CapEx | C15: Fingerprint
B16: CapEx | C16: Hard Drives
B17: CapEx | C17: Heater
... B32: Cost of Sales | C32: Templates
B33: Cost of Sales | C33: Sales Comissions | E33: Internal, External
B34: Cost of Sales | C34: Outsourcing
B35: Cost of Sales | C35: Hosting
B36: Cost of Sales | C36: Ads Spend
B37: Cost of Sales | C37: Subscriptions
B38: Cost of Sales | C38: Plugins
B39: Cost of Sales | C39: Domains
B40: Investment | C40: Balance Swap | D40: Moving a balance from one account to another
B41: Investment | C41: imprest fund | D41: Partner salary payment
B42: Investment | C42: Borrowing | D42: When one account borrows from another
B43: Investment | C43: Refund | D43: When one account refunds an amount borrowed
B44: Investment | C44: Funding
B45: OpEx | C45: Rent
B46: OpEx | C46: Consumables
B47: OpEx | C47: Office Supplies
B48: OpEx | C48: Services
B49: OpEx | C49: Bills | E49: Building,
B50: OpEx | C50: Internet
B51: OpEx | C51: Utilities
B52: OpEx | C52: Transportation | E52: Collection, Meeting, Delivery, Shopping
B53: OpEx | C53: Bank Charges
B54: OpEx | C54: Marketing
B55: Payroll | C55: Salaries
B56: Sunk | C56: Legal
...
