Workbook

Sheet Growth
B2: Aura Systems - Software Department
B3: Income Budget based on Growth
B4: Financial Numbers in EGP
M5: collection & expected | P5: Pricing Structure
B6: Growth Method | C6: 2015 | D6: 2016 | E6: 2017 | F6: 2018 | G6: 2019 | H6: 2020 | I6: 2021 | J6: 2022 | K6: 2023 | L6: 2024 | M6: 2025 | N6: 2026 | P6: 2022 | Q6: 2023 | R6: 2024 | S6: % | T6: 2025 | U6: %2 | V6: 2026 | W6: %3
B7: Products | C7: =SUM('[1]Income 2015'!$F$17:$Q$17) -> 0 | D7: =SUM('[2]Income 2016'!$F$17:$Q$17) -> 0 | E7: =SUM('[3]Income 2017'!$F$17:$Q$17) -> 37100 | F7: =SUM('[4]Income 2018'!$F$17:$Q$17) -> 117830 | G7: =SUM('[5]Income 2019'!$F$18:$Q$18) -> 12500 | H7: 30000 | I7: 34200 | J7: 40000 | K7: 0 | L7: =SUM([6]Total!$R$21:$R$22) -> 0 | M7: =SUM([7]Total!$M$21:$Q$22) -> 2140293.1 | N7: 2000000 | P7: 575 | Q7: 625 | R7: 800 | S7: =R7/Q7 -> 1.28 | T7: 1100 | U7: =Table5[[#This Row],[2025]]/Table5[[#This Row],[2024]] -> 1.375 | V7: 1250 | W7: =Table5[[#This Row],[2026]]/Table5[[#This Row],[2025]] -> 1.1363636
B8: PHP | C8: =SUM('[1]Income 2015'!$F$13:$Q$13) -> 185600 | D8: =SUM('[2]Income 2016'!$F$13:$Q$13) -> 447256 | E8: =SUM('[3]Income 2017'!$F$13:$Q$13) -> 307494 | F8: =SUM('[4]Income 2018'!$F$13:$Q$13) -> 966268.38 | G8: =SUM('[5]Income 2019'!$F$22:$Q$22) -> 826638.18 | H8: 1100000 | I8: =-1280000+2497000+300000 -> 1517000 | J8: =1630000*0.65+46000+50000+70000 -> 1225500 | K8: =1456884*12/10 -> 1748260.8 | L8: =SUM([6]Total!$R$6:$R$7) -> 2649665.9 | M8: =SUM([7]Total!$F$6:$P$7)*12/11 -> 3678723.6 | N8: 4700000 | P8: 575 | Q8: 625 | R8: 800 | S8: =R8/Q8 -> 1.28 | T8: 975 | U8: =Table5[[#This Row],[2025]]/Table5[[#This Row],[2024]] -> 1.21875 | V8: 1150 | W8: =Table5[[#This Row],[2026]]/Table5[[#This Row],[2025]] -> 1.1794872
B9: .NET | L9: =SUM([6]Total!$R$26:$R$27) -> 2799353.7 | M9: =SUM([7]Total!$F$26:$P$27)*12/11 -> 3514572.5 | N9: 4400000 | P9: 525 | Q9: 575 | R9: 800 | S9: =R9/Q9 -> 1.3913043 | T9: 975 | U9: =Table5[[#This Row],[2025]]/Table5[[#This Row],[2024]] -> 1.21875 | V9: 1150 | W9: =Table5[[#This Row],[2026]]/Table5[[#This Row],[2025]] -> 1.1794872
B10: Mobile Development | C10: 0 | D10: =SUM('[2]Income 2016'!$F$37:$Q$37) -> 33900 | E10: =SUM('[3]Income 2017'!$F$37:$Q$37) -> 84187.25 | F10: =SUM('[4]Income 2018'!$F$37:$Q$37) -> 0 | G10: =SUM('[5]Income 2019'!$F$26:$Q$26) -> 5000 | H10: 0 | I10: =680694+300000 -> 980694 | J10: =1630000*0.4 -> 652000 | K10: =348985*12/10 -> 418782 | L10: =SUM([6]Total!$R$11:$R$12) -> 899561.66 | M10: =SUM([7]Total!$F$11:$P$12)*12/11 -> 1442787.5 | N10: 2500000 | P10: 575 | Q10: 625 | R10: 800 | S10: =R10/Q10 -> 1.28 | T10: 975 | U10: =Table5[[#This Row],[2025]]/Table5[[#This Row],[2024]] -> 1.21875 | V10: 1150 | W10: =Table5[[#This Row],[2026]]/Table5[[#This Row],[2025]] -> 1.1794872
B11: Support Contracts | C11: =SUM('[1]Income 2015'!$F$29:$Q$29) -> 0 | D11: =SUM('[2]Income 2016'!$F$29:$Q$29) -> 0 | E11: =SUM('[3]Income 2017'!$F$29:$Q$29) -> 0 | F11: =SUM('[4]Income 2018'!$F$29:$Q$29) -> 11920 | G11: =SUM('[5]Income 2019'!$F$30:$Q$30) -> 155639.87 | H11: 120000 | I11: 160020 | J11: 185595 | L11: 0 | M11: 0 | N11: 0 | P11: =(P8+P12)/2 -> 525 | Q11: =(Q8+Q12)/2 -> 587.5 | R11: =(R8+R12)/2 -> 762.5 | S11: =R11/Q11 -> 1.2978723 | T11: 0 | U11: =Table5[[#This Row],[2025]]/Table5[[#This Row],[2024]] -> 0 | V11: 0 | W11: 0
B12: Websites | C12: =SUM('[1]Income 2015'!$F$25:$Q$25) -> 12750 | D12: =SUM('[2]Income 2016'!$F$25:$Q$25) -> 61008.1 | E12: =SUM('[3]Income 2017'!$F$25:$Q$25) -> 189884.75 | F12: =SUM('[4]Income 2018'!$F$25:$Q$25) -> 278837.53 | G12: =SUM('[5]Income 2019'!$F$39:$Q$39) -> 438820.47 | H12: 505000 | I12: 468300 | J12: 325000 | K12: =372000*12/11 -> 405818.18 | L12: =SUM([6]Total!$R$16:$R$17) -> 1066495.9 | M12: =SUM([7]Total!$F$16:$P$17)*12/11 -> 694293.43 | N12: 1100000 | P12: 475 | Q12: 550 | R12: 725 | S12: =R12/Q12 -> 1.3181818 | T12: 875 | U12: =Table5[[#This Row],[2025]]/Table5[[#This Row],[2024]] -> 1.2068966 | V12: 1050 | W12: =Table5[[#This Row],[2026]]/Table5[[#This Row],[2025]] -> 1.2
B13: Design | J13: 23000 | K13: 75000 | L13: =SUM([6]Total!$R$30:$R$31) -> 100918.11 | M13: =SUM([7]Total!$F$31:$P$32)*12/11 -> 314078.48 | N13: 400000 | Q13: 550 | R13: 725 | S13: =R13/Q13 -> 1.3181818 | T13: 875 | U13: =Table5[[#This Row],[2025]]/Table5[[#This Row],[2024]] -> 1.2068966 | V13: 1050 | W13: =Table5[[#This Row],[2026]]/Table5[[#This Row],[2025]] -> 1.2
B14: Hosting | C14: 0 | D14: 0 | E14: 0 | F14: 0 | G14: =SUM('[5]Income 2019'!$F$43:$Q$43) -> 62052.335 | H14: 45000 | I14: 80107 | J14: 124000 | K14: 406043 | L14: =SUM([6]Total!$R$36:$R$37) -> 373282.56 | M14: =SUM([7]Total!$F$36:$P$37)*12/11 -> 376829.19 | N14: 362000 | P14: =120*P15*1.05*1.14 -> 2243.6568 | Q14: =120*Q15*1.05*1.14 -> 3418.632 | R14: =120*R15*1.05*1.14 -> 4444.2216 | S14: =R14/Q14 -> 1.3 | T14: =150*T15*1.05*1.14 -> 8797.95 | U14: =Table5[[#This Row],[2025]]/Table5[[#This Row],[2024]] -> 1.979638 | V14: =150*V15*1.05*1.14 -> 8456.805 | W14: =Table5[[#This Row],[2026]]/Table5[[#This Row],[2025]] -> 0.96122449
B15: Total | C15: =SUM(C7:C14) -> 198350 | D15: =SUM(D7:D14) -> 542164.1 | E15: =SUM(E7:E14) -> 618666 | F15: =SUM(F7:F14) -> 1374855.9 | G15: =SUM(G7:G14) -> 1500650.9 | H15: =SUM(H7:H14) -> 1800000 | I15: =SUM(I7:I14) -> 3240321 | J15: =SUM(J7:J14) -> 2575095 | ... N15: =SUM(N7:N14) -> 15462000 | P15: 15.62 | Q15: 23.8 | R15: 30.94 | S15: =R15/Q15 -> 1.3 | T15: 49 | U15: =Table5[[#This Row],[2025]]/Table5[[#This Row],[2024]] -> 1.5837104 | V15: 47.1 | W15: =Table5[[#This Row],[2026]]/Table5[[#This Row],[2025]] -> 0.96122449
G16: =G15/F15 -> 1.0914968 | H16: =H15/G15 -> 1.1994795 | I16: =I15/H15 -> 1.8001783 | J16: =J15/I15 -> 0.79470367 | K16: =K15/J15 -> 1.1859384 | L16: =L15/K15 -> 2.5833418 | M16: =M15/L15 -> 1.5415324 | N16: =N15/M15 -> 1.2713811

Sheet Activity
B2: Aura Systems - Software Department
B3: Income Budget based on Activities
B4: Financial Numbers in EGP
B6: VAT Rate | C6: 0.14
B8: 0. Summary
B9: Activity Method
B10: Activity | C10: Total | D10: 2023 | E10: Growth
B11: Support Contracts | C11: =O61 -> 362178 | D11: 400000 | E11: =Table12[[#This Row],[Total]]/Table12[[#This Row],[2023]]-1 -> -0.094555
B12: Custom Development | C12: =O108 -> 2664180 | D12: =Growth!K8 -> 1748260.8 | E12: =Table12[[#This Row],[Total]]/Table12[[#This Row],[2023]]-1 -> 0.52390307
B13: Products | C13: =O117 -> 123120 | D13: =Growth!K7 -> 0 | E13: =Table12[[#This Row],[Total]]/Table12[[#This Row],[2023]]-1 -> #DIV/0!
B14: Websites | C14: =O136 -> 873840 | D14: =Growth!K12 -> 405818.18 | E14: =Table12[[#This Row],[Total]]/Table12[[#This Row],[2023]]-1 -> 1.1532796
B15: Hosting | C15: =O149 -> 215070 | D15: =Growth!K14 -> 406043 | E15: =Table12[[#This Row],[Total]]/Table12[[#This Row],[2023]]-1 -> -0.47032703
B16: Mobile Development | C16: =O184 -> 1207260 | D16: =Growth!K10 -> 418782 | E16: =Table12[[#This Row],[Total]]/Table12[[#This Row],[2023]]-1 -> 1.8827887
B17: Design | C17: =[8]!Table2[[#Totals],[Total]] -> #REF! | D17: =Growth!K13 -> 75000 | E17: =Table12[[#This Row],[Total]]/Table12[[#This Row],[2023]]-1 -> #REF!
B18: .NET | C18: =[8]!Table2[[#Totals],[Total]] -> #REF! | D18: =Growth!K9 -> 0 | E18: =Table12[[#This Row],[Total]]/Table12[[#This Row],[2023]]-1 -> #REF!
C19: =SUBTOTAL(109,Table12[Total]) -> #REF! | D19: =SUBTOTAL(109,Table12[2023]) -> 3453904 | E19: =Table12[[#Totals],[Total]]/Table12[[#Totals],[2023]] -> #REF!
B21: 1. Support Contracts
B22: Support Retainer Pricing
C23: Value
B24: iScore SME | C24: =2.5*3000*1.14 -> 8550
B25: iScore ECR | C25: =2.5*3000*1.14 -> 8550
B26: Smart Furniture | C26: =3500*1.14 -> 3990
B27: Cheers | C27: =3500*1.14 -> 3990
B28: I Make This | C28: =2600*1.14 -> 2964
B29: EEP Hayah | C29: =1500*1.14 -> 1710
B30: Spoon | C30: =1000*1.14 -> 1140
B35: Support Retainer Contracts
C36: 44927 | D36: 44958 | E36: 44986 | F36: 45017 | G36: 45047 | H36: 45078 | I36: 45108 | J36: 45139 | K36: 44805 | L36: 45200 | M36: 45231 | N36: 45261 | O36: Total
B37: =B24 -> iScore SME | C37: 1 | D37: 1 | E37: 1 | F37: 1 | G37: 1 | H37: 1 | I37: 1 | J37: 1 | K37: 1 | L37: 1 | M37: 1 | N37: 1 | O37: =SUM(C37:N37) -> 12
B38: =B25 -> iScore ECR | C38: 1 | D38: 1 | E38: 1 | F38: 1 | G38: 1 | H38: 1 | I38: 1 | J38: 1 | K38: 1 | L38: 1 | M38: 1 | N38: 1 | O38: =SUM(C38:N38) -> 12
B39: =B26 -> Smart Furniture | C39: 1 | D39: 1 | E39: 1 | F39: 1 | G39: 1 | H39: 1 | I39: 1 | J39: 1 | K39: 1 | L39: 1 | M39: 1 | N39: 1 | O39: =SUM(C39:N39) -> 12
B40: =B27 -> Cheers | C40: 1 | D40: 1 | E40: 1 | F40: 1 | G40: 1 | H40: 1 | I40: 1 | J40: 1 | K40: 1 | L40: 1 | M40: 1 | N40: 1 | O40: =SUM(C40:N40) -> 12
B41: =B28 -> I Make This | C41: 1 | D41: 1 | E41: 1 | F41: 1 | G41: 1 | H41: 1 | I41: 1 | J41: 1 | K41: 1 | L41: 1 | M41: 1 | N41: 1 | O41: =SUM(C41:N41) -> 12
B42: =B29 -> EEP Hayah | C42: 1 | D42: 1 | E42: 1 | F42: 0 | G42: 0 | H42: 0 | I42: 0 | J42: 1 | K42: 1 | L42: 1 | M42: 1 | N42: 0 | O42: =SUM(C42:N42) -> 7
B43: =B30 -> Spoon | C43: 1 | D43: 1 | E43: 1 | F43: 1 | G43: 1 | H43: 1 | I43: 1 | J43: 1 | K43: 1 | L43: 1 | M43: 1 | N43: 1 | O43: =SUM(C43:N43) -> 12
B44: =B31 -> 0 | O44: =SUM(C44:N44) -> 0
B45: =B32 -> 0 | O45: =SUM(C45:N45) -> 0
B46: =B33 -> 0 | O46: =SUM(C46:N46) -> 0
B47: Total Retainer Contracts | C47: =SUM(C37:C46) -> 7 | D47: =SUM(D37:D46) -> 7 | E47: =SUM(E37:E46) -> 7 | F47: =SUM(F37:F46) -> 6 | G47: =SUM(G37:G46) -> 6 | H47: =SUM(H37:H46) -> 6 | I47: =SUM(I37:I46) -> 6 | J47: =SUM(J37:J46) -> 7 | ... O47: =SUM(O37:O46) -> 79
B49: Support Retainer Sales
...

Sheet Allocation
B2: Aura Systems - Software Department
B3: Income Budget based on Allocation
B4: Financial Numbers in EGP
B6: Custom Development
C7: 2021 | D7: % | F7: Improvement Factors
B8: Headcount | C8: 7.5 | F8: Training | G8: 0.05
B9: Revenue | C9: =Growth!I8 -> 1517000 | F9: Pricing | G9: =C21/C10-1 -> #DIV/0!
B10: Monthly Price | F10: Process | G10: 0.03
B11: Cost of Sales | D11: =C11/C9 -> 0 | F11: Allocation | G11: 0.03
B12: Salaries | D12: =C12/C9 -> 0 | F12: Total | G12: =SUM(G8:G11) -> #DIV/0!
B13: OpEx | D13: =C13/C9 -> 0
B14: Taxes | D14: =C14/C9 -> 0
B15: Earnings | C15: =[9]Software!$O$34 -> 207907.42 | D15: =C15/C9 -> 0.13705169
B16: Revenue per Head | C16: =C9/C8 -> 202266.67
B17: Earnings per Head | C17: =C15/C8 -> 27720.989
C19: 2022
B20: Headcount | C20: 12
B21: =B10 -> Monthly Price | C21: =Activity!C64 -> 64980
B22: % Improvement | C22: =G12 -> #DIV/0!
B23: Revenue per head | C23: =C16*(1+C22) -> #DIV/0!
B24: Revenue | C24: =C20*C23 -> #DIV/0!
B25: Cost of Sales | C25: =D11*C24 -> #DIV/0!
B26: Salaries
B27: OpEx | C27: =D13*C24 -> #DIV/0!
B28: Taxes | C28: =D14*C24 -> #DIV/0!
B29: Earnings | C29: =C24-SUM(C25:C28) -> #DIV/0! | D29: =C29/C24 -> #DIV/0!
B30: Earnings per Head | C30: =C29/C20 -> #DIV/0!
B33: Websites
C34: 2021 | D34: % | F34: Improvement Factors
B35: Headcount | C35: 3 | F35: Training | G35: 0.05
B36: Revenue | C36: =[9]Websites!$O$11 -> 502514.99 | F36: Pricing | G36: =C48/C37-1 -> 0.47730405
B37: Average Contract | C37: =[9]Websites!$O$47 -> 22321.129 | F37: Process | G37: 0.1
B38: Cost of Sales | C38: =[9]Websites!$O$14 -> 64953.426 | D38: =C38/C36 -> 0.12925669 | F38: Allocation | G38: 0.03
B39: Salaries | C39: =[9]Websites!$O$20 -> 298750.89 | D39: =C39/C36 -> 0.59451139 | F39: Total | G39: =SUM(G35:G38) -> 0.65730405
B40: OpEx | C40: =[9]Websites!$O$25 -> 2058.05 | D40: =C40/C36 -> 0.0040954997
B41: Taxes | C41: =[9]Websites!$O$30 -> 44645.245 | D41: =C41/C36 -> 0.088843608
B42: Earnings | C42: =[9]Websites!$O$32 -> 92107.385 | D42: =C42/C36 -> 0.18329281
B43: Revenue per Head
B44: Earnings per Head | C44: =[9]Websites!$O$38*12 -> 277847.18
C46: 2022
...

Sheet Capacity
B2: Aura Systems - Software Department
B3: Income Budget based on Capacity
B4: Financial Numbers in EGP
B6: 2026 | C6: Product | D6: PHP | E6: .Net | F6: Mobile | H6: Websites | I6: Design
B7: Head Count | C7: 1 | D7: 3 | E7: 3 | F7: 1 | H7: 1 | I7: 1 | J7: =SUM(D7:I7) -> 9
B8: Avg billable hours per Emp | C8: 160 | D8: 120 | E8: 120 | F8: 120 | H8: 120 | I8: 60
C9: 0.9 | D9: 0.85 | E9: 0.85 | F9: 0.9 | H9: 0.8 | I9: 0.55
B10: Hour Price | C10: =Growth!V7 -> 1250 | D10: =Growth!V8 -> 1150 | E10: =Growth!V9 -> 1150 | F10: =Growth!V10 -> 1150 | H10: =Growth!V12 -> 1050 | I10: =Growth!V13 -> 1050
B11: Total | C11: =C7*C8*C10*12*C9*1.14 -> 2462400 | D11: =D7*D8*D10*12*D9*1.14 -> 4813992 | E11: =E7*E8*E10*12*E9*1.14 -> 4813992 | F11: =F7*F8*F10*12*F9*1.14 -> 1699056 | H11: =H7*H8*H10*12*H9*1.14 -> 1378944 | I11: =I7*I8*I10*12*I9*1.14 -> 474012 | J11: =SUM(D11:I11) -> 13179996 | K11: =J11/J7 -> 1464444
C12: =C8*C9 -> 144 | D12: =D8*D9 -> 102 | E12: =E8*E9 -> 102 | F12: =F8*F9 -> 108 | H12: =H8*H9 -> 96 | I12: =I8*I9 -> 33
B13: Monthly | C13: =C12*C10 -> 180000 | D13: =D12*D10 -> 117300 | E13: =E12*E10 -> 117300 | F13: =F12*F10 -> 124200 | H13: =H12*H10 -> 100800 | I13: =I12*I10 -> 34650
B16: 2025 | C16: Product | D16: PHP | E16: .NET | F16: Mobile | H16: Websites | I16: Design
B17: Head Count | C17: 1 | D17: 3 | E17: 3 | F17: 1 | H17: 1.5 | I17: 1 | J17: =SUM(D17:I17) -> 9.5
B18: Avg billable hours per Emp | C18: 160 | D18: =D8 -> 120 | E18: 120 | F18: =F8 -> 120 | H18: =H8 -> 120 | I18: =I8 -> 60
C19: =C21/1.14/C20/12/C17/C18 -> 0.88894419 | D19: =D21/1.14/D20/12/D17/D18 -> 0.76613259 | E19: =E21/1.14/E20/12/E17/E18 -> 0.73194642 | F19: =F21/1.14/F20/12/F17/F18 -> 0.90142667 | H19: =H21/1.14/H20/12/H17/H18 -> 0.32223774 | I19: =I21/1.14/I20/12/I17/I18 -> 0.43731339
B20: Hour Price | C20: =Growth!T7 -> 1100 | D20: =Growth!T8 -> 975 | E20: =Growth!T9 -> 975 | F20: =Growth!T10 -> 975 | H20: =Growth!T12 -> 875 | I20: =Growth!T13 -> 875
B21: Total | C21: =Growth!M7 -> 2140293.1 | D21: =Growth!M8 -> 3678723.6 | E21: =Growth!M9 -> 3514572.5 | F21: =Growth!M10 -> 1442787.5 | H21: =Growth!M12 -> 694293.43 | I21: =Growth!M13 -> 314078.48 | J21: =SUM(D21:I21) -> 9644455.4 | K21: =J21/J17 -> 1015205.8
B22: Billable Hours per Month/Emp | C22: =C19*C18 -> 142.23107 | D22: =D19*D18 -> 91.935911 | E22: =E19*E18 -> 87.833571 | F22: =F19*F18 -> 108.1712 | H22: =H19*H18 -> 38.668528 | I22: =I19*I18 -> 26.238803
B23: Total Worked Hours | C23: 100 | D23: 100 | E23: 100 | F23: 100 | H23: 100 | I23: =436.47/11 -> 39.679091
B24: Billable/total | C24: =C22/C23 -> 1.4223107 | D24: =D22/D23 -> 0.91935911 | E24: =E22/E23 -> 0.87833571 | F24: =F22/F23 -> 1.081712 | H24: =H22/H23 -> 0.38668528 | I24: =I22/I23 -> 0.66127531
B25: Improvement Needed 2024 | C25: =C9/C19 -> 1.012437 | D25: =D9/D19 -> 1.1094685 | E25: =E9/E19 -> 1.1612872 | F25: =F9/F19 -> 0.99841732 | H25: =H9/H19 -> 2.4826391 | I25: =I9/I19 -> 1.2576793
D27: =(110-D22)*D17*12*D20 -> 634049.51 | E27: =(110-E22)*E17*12*E20 -> 778041.67 | H27: =(110-H22)*H17*12*H20 -> 1123470.7

Sheet Collection
A1: Aura Systems - Software Department
A2: Income Budget based on Activities
A3: Financial Numbers in EGP
A5: VAT Rate | B5: 0.14
A7: 0. Summary
A8: Collection Method
A9: Activity | B9: Total | C9: 2025 | D9: Increase
A10: Support Contracts | B10: 0 | C10: 0
A11: PHP | B11: =B45 -> 5074263.8 | C11: =Growth!M8 -> 3678723.6 | D11: =Table124[[#This Row],[Total]]/Table124[[#This Row],[2025]]-100% -> 0.37935447
A12: Products | B12: =B71 -> 3014068 | C12: =Growth!M7 -> 2140293.1 | D12: =Table124[[#This Row],[Total]]/Table124[[#This Row],[2025]]-100% -> 0.40825009
A13: Websites | B13: =B110 -> 1027762 | C13: =Growth!M12 -> 694293.43 | D13: =Table124[[#This Row],[Total]]/Table124[[#This Row],[2025]]-100% -> 0.48029918
A14: Hosting | B14: =B84 -> 945997.36 | C14: =Growth!M14 -> 376829.19 | D14: =Table124[[#This Row],[Total]]/Table124[[#This Row],[2025]]-100% -> 1.5104142
A15: Mobile Developmet | B15: =B122 -> 3004332.9 | C15: =Growth!M10 -> 1442787.5 | D15: =Table124[[#This Row],[Total]]/Table124[[#This Row],[2025]]-100% -> 1.0823115
A16: Design | B16: =B134 -> 411106.03 | C16: =Growth!M13 -> 314078.48 | D16: =Table124[[#This Row],[Total]]/Table124[[#This Row],[2025]]-100% -> 0.30892775
A17: .NET | B17: =B58 -> 2584367 | C17: =Growth!M9 -> 3514572.5 | D17: =Table124[[#This Row],[Total]]/Table124[[#This Row],[2025]]-100% -> -0.26467101
B18: =SUBTOTAL(109,Table124[Total]) -> 16061897 | C18: =SUBTOTAL(109,Table124[2025]) -> 12161578 | D18: =(Table124[[#Totals],[Total]]/Table124[[#Totals],[2025]])-100% -> 0.32070834
A22: 2025
A23: Activity | B23: Beginning Balance | C23: End Balance | D23: Average
A24: Support Contracts | B24: 0 | C24: 0
A25: PHP | B25: =[10]Total!$E$3 -> 330066.52 | C25: =[10]Total!$R$3 -> 852855.96 | D25: =(B25+C25)/2 -> 591461.24
A26: Products | B26: =[10]Total!$E$18 -> 0 | C26: =[10]Total!$R$18 -> 909243.85 | D26: =(B26+C26)/2 -> 454621.92
A27: Websites | B27: =[10]Total!$E$13 -> 245176.91 | C27: =[10]Total!$R$13 -> 352236.76 | D27: =(B27+C27)/2 -> 298706.83
A28: Hosting | B28: =[10]Total!$E$33 -> 152020.96 | C28: =[10]Total!$R$33 -> 351300.14 | D28: =(B28+C28)/2 -> 251660.55
A29: Mobile Developmet | B29: =[10]Total!$E$8 -> 451215 | C29: =[10]Total!$R$8 -> 1405820.7 | D29: =(B29+C29)/2 -> 928517.86
A30: =A16 -> Design | B30: =[10]Total!$E$28 -> 78240.2 | C30: =[10]Total!$R$28 -> 135950.71 | D30: =(B30+C30)/2 -> 107095.45
A31: =A17 -> .NET | B31: =[10]Total!$E$23 -> 220381 | C31: =[10]Total!$R$23 -> 235120.93 | D31: =(B31+C31)/2 -> 227750.97
A32: Total | B32: =SUM(B24:B31) -> 1477100.6 | C32: =SUM(C24:C31) -> 4242529.1 | D32: =(B32+C32)/2 -> 2859814.8
A36: PHP
A37: Average Contract per month | B37: =SUM([10]Total!$R$4:$R$5)/12 -> 347717.47
A38: Average Collection per Month | B38: =SUM([10]Total!$R$6:$R$7)/12 -> 353365.26
A39: Collection Months | B39: =D25/B38 -> 1.6737956
A41: =A36 -> PHP | F41: 1 | G41: 2 | H41: 3 | I41: 4 | J41: 5 | K41: 6 | L41: 7 | M41: 8 | N41: 9 | O41: 10 | P41: 11 | Q41: 12
A42: Jan2026 Balance | B42: =C25 -> 852855.96 | D42: 0.2 | F42: 0.6 | G42: 0.4
A43: Collection Months 2026 | B43: =(F46+B39)/2 -> 2.0168978 | D43: 0.4 | F43: 0.3 | G43: 0.3 | H43: 0.3 | I43: 0.1
A44: Collection per month | B44: =B42/B43 -> 422855.31 | D44: 0.4 | F44: 0.2 | G44: 0.2 | H44: 0.2 | I44: 0.2 | J44: 0.2
A45: Total | B45: =B44*12 -> 5074263.8 | D45: Coll | F45: =($D$42*F42)+($D$43*F43)+($D$44*F44) -> 0.32 | G45: =($D$42*G42)+($D$43*G43)+($D$44*G44) -> 0.28 | H45: =($D$42*H42)+($D$43*H43)+($D$44*H44) -> 0.2 | I45: =($D$42*I42)+($D$43*I43)+($D$44*I44) -> 0.12 | J45: =($D$42*J42)+($D$43*J43)+($D$44*J44) -> 0.08 | K45: =($D$42*K42)+($D$43*K43)+($D$44*K44) -> 0 | L45: =($D$42*L42)+($D$43*L43)+($D$44*L44) -> 0 | M45: =($D$42*M42)+($D$43*M43)+($D$44*M44) -> 0 | ... Q45: =($D$42*Q42)+($D$43*Q43)+($D$44*Q44) -> 0
F46: =SUMPRODUCT(F45:Q45,F41:Q41) -> 2.36
A49: .Net
A50: Average Contract per month | B50: =SUM([10]Total!$R$24:$R$25)/12 -> 299536.43
A51: Average Collection per Month | B51: =SUM([10]Total!$R$26:$R$27)/12 -> 298308.11
...

Sheet Result
B2: Aura Systems - Software Department
B3: Income Budget Results
B4: Financial Numbers in EGP
H5: 2026 | L5: 2025 | P5: Pricing Structure
B6: Item | C6: Extrapolation | D6: Capacity | E6: Collection | F6: Collection Adj | G6: Average | H6: Final | I6: Monthly | J6: Hours/Mth | K6: Employees | L6: Final | M6: Monthly | N6: Monthly +% | P6: 2022 | Q6: 2023 | R6: 2024 | S6: 2025 | T6: 2026 | U6: % | V6: USD$
B7: =Growth!B7 -> Products | C7: =Growth!N7 -> 2000000 | D7: =Capacity!C11 -> 2462400 | E7: =Collection!B12 -> 3014068 | F7: =E7*1.3 -> 3918288.4 | G7: =AVERAGE(C7:E7) -> 2492156 | H7: 2500000 | I7: =H7/12 -> 208333.33 | J7: =I7/(Table57[[#This Row],[2025]]*1.14) -> 166.13503 | K7: 1 | L7: =Growth!M7 -> 2140293.1 | M7: =L7/12 -> 178357.76 | N7: =M7*Table57[[#This Row],[%]] -> 218893.62 | P7: =Table5[[#This Row],[2022]] -> 575 | Q7: =Table5[[#This Row],[2023]] -> 625 | R7: =Table5[[#This Row],[2024]] -> 800 | S7: =Table5[[#This Row],[2025]] -> 1100 | T7: 1350 | U7: =Table57[[#This Row],[2026]]/Table57[[#This Row],[2025]] -> 1.2272727 | V7: =Table57[[#This Row],[2026]]/$T$15 -> 27.55102
B8: =Growth!B8 -> PHP | C8: =Growth!N8 -> 4700000 | D8: =Capacity!D11 -> 4813992 | E8: =Collection!B11 -> 5074263.8 | F8: =E8*1.3 -> 6596542.9 | G8: =AVERAGE(C8:E8) -> 4862751.9 | H8: 4800000 | I8: =H8/12 -> 400000 | J8: =I8/(Table57[[#This Row],[2025]]*1.14) -> 359.87404 | K8: 3 | L8: =Growth!M8 -> 3678723.6 | M8: =L8/12 -> 306560.3 | N8: =M8*Table57[[#This Row],[%]] -> 361583.94 | P8: =Table5[[#This Row],[2022]] -> 575 | Q8: =Table5[[#This Row],[2023]] -> 625 | R8: =Table5[[#This Row],[2024]] -> 800 | S8: =Table5[[#This Row],[2025]] -> 975 | T8: =Table5[[#This Row],[2026]] -> 1150 | U8: =Table57[[#This Row],[2026]]/Table57[[#This Row],[2025]] -> 1.1794872 | V8: =Table57[[#This Row],[2026]]/$T$15 -> 23.469388
B9: .NET | C9: =Growth!N9 -> 4400000 | D9: =Capacity!E11 -> 4813992 | E9: =Collection!B17 -> 2584367 | F9: =E9*1.3 -> 3359677.1 | G9: =AVERAGE(C9:E9) -> 3932786.3 | H9: 4200000 | I9: =H9/12 -> 350000 | J9: =I9/(Table57[[#This Row],[2025]]*1.14) -> 314.88979 | K9: 3 | L9: =Growth!M9 -> 3514572.5 | M9: =L9/12 -> 292881.04 | N9: =M9*Table57[[#This Row],[%]] -> 345449.43 | P9: =Table5[[#This Row],[2022]] -> 525 | Q9: =Table5[[#This Row],[2023]] -> 575 | R9: =Table5[[#This Row],[2024]] -> 800 | S9: =Table5[[#This Row],[2025]] -> 975 | T9: =Table5[[#This Row],[2026]] -> 1150 | U9: =Table57[[#This Row],[2026]]/Table57[[#This Row],[2025]] -> 1.1794872 | V9: =Table57[[#This Row],[2026]]/$T$15 -> 23.469388
B10: =Growth!B10 -> Mobile Development | C10: =Growth!N10 -> 2500000 | D10: =Capacity!F11 -> 1699056 | E10: =Collection!B15 -> 3004332.9 | F10: =E10*1.3 -> 3905632.8 | G10: =AVERAGE(C10:E10) -> 2401129.6 | H10: 2000000 | I10: =H10/12 -> 166666.67 | J10: =I10/(Table57[[#This Row],[2025]]*1.14) -> 149.94752 | K10: 1 | L10: =Growth!M10 -> 1442787.5 | M10: =L10/12 -> 120232.29 | N10: =M10*Table57[[#This Row],[%]] -> 141812.44 | P10: =Table5[[#This Row],[2022]] -> 575 | Q10: =Table5[[#This Row],[2023]] -> 625 | R10: =Table5[[#This Row],[2024]] -> 800 | S10: =Table5[[#This Row],[2025]] -> 975 | T10: =Table5[[#This Row],[2026]] -> 1150 | U10: =Table57[[#This Row],[2026]]/Table57[[#This Row],[2025]] -> 1.1794872 | V10: =Table57[[#This Row],[2026]]/$T$15 -> 23.469388
B11: =Growth!B11 -> Support Contracts | C11: =Growth!N11 -> 0 | D11: =Capacity!G11 -> 0 | E11: 0 | F11: =E11*1.3 -> 0 | G11: =AVERAGE(C11:E11) -> 0 | I11: =H11/12 -> 0 | K11: 0 | M11: =L11/12 -> 0 | N11: =M11*Table57[[#This Row],[%]] -> 0 | P11: =Table5[[#This Row],[2022]] -> 525 | Q11: =Table5[[#This Row],[2023]] -> 587.5 | R11: =Table5[[#This Row],[2024]] -> 762.5 | S11: 0 | T11: 0 | U11: 0 | V11: =Table57[[#This Row],[2026]]/$T$15 -> 0
B12: =Growth!B12 -> Websites | C12: =Growth!N12 -> 1100000 | D12: =Capacity!H11 -> 1378944 | E12: =Collection!B13 -> 1027762 | F12: =E12*1.3 -> 1336090.6 | G12: =AVERAGE(C12:E12) -> 1168902 | H12: 1100000 | I12: =H12/12 -> 91666.667 | J12: =I12/(Table57[[#This Row],[2025]]*1.14) -> 91.896408 | K12: 1 | L12: =Growth!M12 -> 694293.43 | M12: =L12/12 -> 57857.786 | N12: =M12*Table57[[#This Row],[%]] -> 69429.343 | P12: =Table5[[#This Row],[2022]] -> 475 | Q12: =Table5[[#This Row],[2023]] -> 550 | R12: =Table5[[#This Row],[2024]] -> 725 | S12: =Table5[[#This Row],[2025]] -> 875 | T12: =Table5[[#This Row],[2026]] -> 1050 | U12: =Table57[[#This Row],[2026]]/Table57[[#This Row],[2025]] -> 1.2 | V12: =Table57[[#This Row],[2026]]/$T$15 -> 21.428571
B13: Design | C13: =Growth!N13 -> 400000 | D13: =Capacity!I11 -> 474012 | E13: =Collection!B16 -> 411106.03 | F13: =E13*1.3 -> 534437.84 | G13: =AVERAGE(C13:E13) -> 428372.68 | H13: 420000 | I13: =H13/12 -> 35000 | J13: =I13/(Table57[[#This Row],[2025]]*1.14) -> 35.087719 | K13: 1 | L13: =Growth!M13 -> 314078.48 | M13: =L13/12 -> 26173.206 | N13: =M13*Table57[[#This Row],[%]] -> 31407.848 | P13: =Table5[[#This Row],[2022]] -> 0 | Q13: =Table5[[#This Row],[2023]] -> 550 | R13: =Table5[[#This Row],[2024]] -> 725 | S13: =Table5[[#This Row],[2025]] -> 875 | T13: =Table5[[#This Row],[2026]] -> 1050 | U13: =Table57[[#This Row],[2026]]/Table57[[#This Row],[2025]] -> 1.2 | V13: =Table57[[#This Row],[2026]]/$T$15 -> 21.428571
B14: =Growth!B14 -> Hosting | C14: =Growth!N14 -> 362000 | E14: =Table124[[#This Row],[Total]] -> 945997.36 | F14: =E14*1.3 -> 1229796.6 | G14: =AVERAGE(C14:E14) -> 653998.68 | H14: 380000 | I14: =H14/12 -> 31666.667 | J14: =I14/(Table57[[#This Row],[2025]]*1.14) -> 3.1573012 | K14: 0 | L14: =Growth!M14 -> 376829.19 | M14: =L14/12 -> 31402.433 | N14: =M14*Table57[[#This Row],[%]] -> 30184.788 | P14: =120*P15*1.05*1.14 -> 2243.6568 | Q14: =120*Q15*1.05*1.14 -> 3418.632 | R14: =120*R15*1.05*1.14 -> 4444.2216 | S14: =Table5[[#This Row],[2025]] -> 8797.95 | T14: =Table5[[#This Row],[2026]] -> 8456.805 | U14: =Table57[[#This Row],[2026]]/Table57[[#This Row],[2025]] -> 0.96122449 | V14: =Table57[[#This Row],[2026]]/$T$15 -> 172.58786
B15: Total | C15: =SUM(C7:C14) -> 15462000 | D15: =SUM(D7:D14) -> 15642396 | E15: =SUM(E7:E14) -> 16061897 | F15: =SUM(F7:F14) -> 20880466 | G15: =SUM(G7:G14) -> 15940097 | H15: =SUM(H7:H14) -> 15400000 | I15: =SUM(I7:I14) -> 1283333.3 | L15: =SUM(L7:L14) -> 12161578 | M15: =SUM(M7:M14) -> 1013464.8 | N15: =SUM(N7:N14) -> 1198761.4 | P15: =Table5[[#This Row],[2022]] -> 15.62 | Q15: =Table5[[#This Row],[2023]] -> 23.8 | R15: =Table5[[#This Row],[2024]] -> 30.94 | S15: 47.65 | T15: 49 | U15: =Table57[[#This Row],[2026]]/Table57[[#This Row],[2025]] -> 1.0283316 | V15: =Table57[[#This Row],[2026]]/$T$15 -> 1
H16: =H15/L15 -> 1.2662831

Sheet Personnel
B2: Aura Systems
B3: Salaries Forecast
B4: Financial Numbers in 000s of EGP
B6: Assumpltions
B7: Variable | C7: Value
B8: Social Insurance | C8: 0.08
B9: 2019 Headcount
B10: Untaxable income | C10: 12
B11: E3fa2 | C11: 13.5
B12: Health Insurance per Employee per month | C12: 0
B14: Salaries Estimates | E14: 2024
B15: Role | C15: Employee | D15: 2025 Net | E15: 2026 | F15: Hourly | G15: SI | H15: Rep | I15: Y Increase | J15: Column1 | K15: Column2 | L15: SI
B16: G&A | J16: =Table4[[#This Row],[2025 Net]]*1.25 -> 0 | K16: =Table4[[#This Row],[2025 Net]]*1.15 -> 0
B17: Admin Assistant | C17: Nermeen | D17: 19.5 | E17: 22.75 | F17: =Table4[[#This Row],[2026]]/140*1000 -> 162.5 | G17: 1.93 | H17: 1 | I17: =Table4[[#This Row],[2026]]/Table4[[#This Row],[2025 Net]]-1 -> 0.16666667 | J17: =Table4[[#This Row],[2025 Net]]*1.25 -> 24.375 | K17: =Table4[[#This Row],[2025 Net]]*1.15 -> 22.425 | L17: =((MIN(Table4[[#This Row],[2026]]*0.8,9.4)*12)-13.5)*0.2975/12 -> 2.4618125
B18: Financial Manager | C18: Fadi | D18: 40 | E18: 0 | F18: =Table4[[#This Row],[2026]]/140*1000 -> 0 | H18: 1 | I18: =Table4[[#This Row],[2026]]/Table4[[#This Row],[2025 Net]]-1 -> -1 | J18: =Table4[[#This Row],[2025 Net]]*1.25 -> 50 | K18: =Table4[[#This Row],[2025 Net]]*1.15 -> 46 | L18: =((MIN(Table4[[#This Row],[2026]]*0.8,9.4)*12)-13.5)*0.2975/12 -> -0.3346875
B19: General Manager | C19: Samer | D19: 90 | E19: 104 | F19: =Table4[[#This Row],[2026]]/140*1000 -> 742.85714 | G19: =MIN(Table4[[#This Row],[2026]],8.1)*0.2975 -> 2.40975 | H19: 1 | I19: =Table4[[#This Row],[2026]]/Table4[[#This Row],[2025 Net]]-1 -> 0.15555556 | J19: =Table4[[#This Row],[2025 Net]]*1.25 -> 112.5 | K19: =Table4[[#This Row],[2025 Net]]*1.15 -> 103.5 | L19: =((MIN(Table4[[#This Row],[2026]]*0.8,9.4)*12)-13.5)*0.2975/12 -> 2.4618125
B20: Technical Lead | C20: TBH | D20: 0 | F20: =Table4[[#This Row],[2026]]/140*1000 -> 0 | G20: =MIN(Table4[[#This Row],[2026]],8.1)*0.2975 -> 2.40975 | H20: 1 | I20: =Table4[[#This Row],[2026]]/Table4[[#This Row],[2025 Net]]-1 -> #DIV/0! | J20: =Table4[[#This Row],[2025 Net]]*1.25 -> 0 | K20: =Table4[[#This Row],[2025 Net]]*1.15 -> 0 | L20: =((MIN(Table4[[#This Row],[2026]]*0.8,9.4)*12)-13.5)*0.2975/12 -> -0.3346875
B21: Sr. Sales | C21: TBH | D21: 0 | F21: =Table4[[#This Row],[2026]]/140*1000 -> 0 | G21: =MIN(Table4[[#This Row],[2026]],8.1)*0.2975 -> 2.40975 | H21: 1 | I21: =Table4[[#This Row],[2026]]/Table4[[#This Row],[2025 Net]]-1 -> #DIV/0! | J21: =Table4[[#This Row],[2025 Net]]*1.25 -> 0 | K21: =Table4[[#This Row],[2025 Net]]*1.15 -> 0 | L21: =((MIN(Table4[[#This Row],[2026]]*0.8,9.4)*12)-13.5)*0.2975/12 -> -0.3346875
B22: Jr. Sales | D22: 0 | F22: =Table4[[#This Row],[2026]]/140*1000 -> 0 | G22: =MIN(Table4[[#This Row],[2026]],8.1)*0.2975 -> 2.40975 | H22: 1 | I22: =Table4[[#This Row],[2026]]/Table4[[#This Row],[2025 Net]]-1 -> #DIV/0! | J22: =Table4[[#This Row],[2025 Net]]*1.25 -> 0 | K22: =Table4[[#This Row],[2025 Net]]*1.15 -> 0 | L22: =((MIN(Table4[[#This Row],[2026]]*0.8,9.4)*12)-13.5)*0.2975/12 -> -0.3346875
B23: Accountant | C23: Mariam | D23: 19.5 | E23: 22.75 | F23: =Table4[[#This Row],[2026]]/140*1000 -> 162.5 | G23: 1.59 | H23: 1 | I23: =Table4[[#This Row],[2026]]/Table4[[#This Row],[2025 Net]]-1 -> 0.16666667 | J23: =Table4[[#This Row],[2025 Net]]*1.25 -> 24.375 | K23: =Table4[[#This Row],[2025 Net]]*1.15 -> 22.425 | L23: =((MIN(Table4[[#This Row],[2026]]*0.8,9.4)*12)-13.5)*0.2975/12 -> 2.4618125
B24: Office Boy | C24: Ibrahim | D24: 12.5 | E24: 14.5 | F24: =Table4[[#This Row],[2026]]/140*1000 -> 103.57143 | G24: 1.81 | H24: 1 | I24: =Table4[[#This Row],[2026]]/Table4[[#This Row],[2025 Net]]-1 -> 0.16 | J24: =Table4[[#This Row],[2025 Net]]*1.25 -> 15.625 | K24: =Table4[[#This Row],[2025 Net]]*1.15 -> 14.375 | L24: =((MIN(Table4[[#This Row],[2026]]*0.8,9.4)*12)-13.5)*0.2975/12 -> 2.4618125
B25: Custom Department | J25: =Table4[[#This Row],[2025 Net]]*1.25 -> 0 | K25: =Table4[[#This Row],[2025 Net]]*1.15 -> 0 | L25: =((MIN(Table4[[#This Row],[2026]]*0.8,9.4)*12)-13.5)*0.2975/12 -> -0.3346875
B26: Engineering Manager | C26: =C19 -> Samer | D26: =D19 -> 90 | E26: =E19 -> 104 | F26: =Table4[[#This Row],[2026]]/140*1000 -> 742.85714 | G26: =MIN(Table4[[#This Row],[2026]],8.1)*0.2975 -> 2.40975 | H26: 1 | I26: =Table4[[#This Row],[2026]]/Table4[[#This Row],[2025 Net]]-1 -> 0.15555556 | J26: =Table4[[#This Row],[2025 Net]]*1.25 -> 112.5 | K26: =Table4[[#This Row],[2025 Net]]*1.15 -> 103.5 | L26: =((MIN(Table4[[#This Row],[2026]]*0.8,9.4)*12)-13.5)*0.2975/12 -> 2.4618125
B27: Mobile Manager | C27: Fadi | D27: =D18 -> 40 | E27: =E18 -> 0 | F27: =Table4[[#This Row],[2026]]/140*1000 -> 0 | G27: =MIN(Table4[[#This Row],[2026]],8.1)*0.2975 -> 0 | H27: 1 | I27: =Table4[[#This Row],[2026]]/Table4[[#This Row],[2025 Net]]-1 -> -1 | J27: =Table4[[#This Row],[2025 Net]]*1.25 -> 50 | K27: =Table4[[#This Row],[2025 Net]]*1.15 -> 46 | L27: =((MIN(Table4[[#This Row],[2026]]*0.8,9.4)*12)-13.5)*0.2975/12 -> -0.3346875
B28: Project Manager | C28: Nathalie | D28: 30 | E28: 35 | F28: =Table4[[#This Row],[2026]]/140*1000 -> 250 | G28: =MIN(Table4[[#This Row],[2026]],8.1)*0.2975 -> 2.40975 | H28: 1 | I28: =Table4[[#This Row],[2026]]/Table4[[#This Row],[2025 Net]]-1 -> 0.16666667 | J28: =Table4[[#This Row],[2025 Net]]*1.25 -> 37.5 | K28: =Table4[[#This Row],[2025 Net]]*1.15 -> 34.5 | L28: =((MIN(Table4[[#This Row],[2026]]*0.8,9.4)*12)-13.5)*0.2975/12 -> 2.4618125
B29: Backend Developer 1 | C29: Hazem | D29: 38 | E29: 44 | F29: =Table4[[#This Row],[2026]]/140*1000 -> 314.28571 | G29: =MIN(Table4[[#This Row],[2026]],8.1)*0.2975 -> 2.40975 | H29: 1 | I29: =Table4[[#This Row],[2026]]/Table4[[#This Row],[2025 Net]]-1 -> 0.15789474 | J29: =Table4[[#This Row],[2025 Net]]*1.25 -> 47.5 | K29: =Table4[[#This Row],[2025 Net]]*1.15 -> 43.7 | L29: =((MIN(Table4[[#This Row],[2026]]*0.8,9.4)*12)-13.5)*0.2975/12 -> 2.4618125
B30: Backend Developer 2 | C30: TBH | D30: 18 | E30: 21 | F30: =Table4[[#This Row],[2026]]/140*1000 -> 150 | G30: 1.81 | H30: 1 | I30: =Table4[[#This Row],[2026]]/Table4[[#This Row],[2025 Net]]-1 -> 0.16666667 | J30: =Table4[[#This Row],[2025 Net]]*1.25 -> 22.5 | K30: =Table4[[#This Row],[2025 Net]]*1.15 -> 20.7 | L30: =((MIN(Table4[[#This Row],[2026]]*0.8,9.4)*12)-13.5)*0.2975/12 -> 2.4618125
B31: Backend Developer 3 | C31: Mostafa | D31: 19 | E31: 21 | F31: =Table4[[#This Row],[2026]]/140*1000 -> 150 | G31: 1.59 | H31: 1 | I31: =Table4[[#This Row],[2026]]/Table4[[#This Row],[2025 Net]]-1 -> 0.10526316 | J31: =Table4[[#This Row],[2025 Net]]*1.25 -> 23.75 | K31: =Table4[[#This Row],[2025 Net]]*1.15 -> 21.85 | L31: =((MIN(Table4[[#This Row],[2026]]*0.8,9.4)*12)-13.5)*0.2975/12 -> 2.4618125
B32: Backend Developer 4 | C32: Shady | D32: 34 | E32: 40 | F32: =Table4[[#This Row],[2026]]/140*1000 -> 285.71429 | G32: =MIN(Table4[[#This Row],[2026]],8.1)*0.2975 -> 2.40975 | H32: 1 | I32: =Table4[[#This Row],[2026]]/Table4[[#This Row],[2025 Net]]-1 -> 0.17647059 | J32: =Table4[[#This Row],[2025 Net]]*1.25 -> 42.5 | K32: =Table4[[#This Row],[2025 Net]]*1.15 -> 39.1 | L32: =((MIN(Table4[[#This Row],[2026]]*0.8,9.4)*12)-13.5)*0.2975/12 -> 2.4618125
B33: Backend Developer 5 | C33: TBH | D33: 17 | E33: 19.5 | F33: =Table4[[#This Row],[2026]]/140*1000 -> 139.28571 | G33: 1.81 | H33: 1 | I33: =Table4[[#This Row],[2026]]/Table4[[#This Row],[2025 Net]]-1 -> 0.14705882 | J33: =Table4[[#This Row],[2025 Net]]*1.25 -> 21.25 | K33: =Table4[[#This Row],[2025 Net]]*1.15 -> 19.55 | L33: =((MIN(Table4[[#This Row],[2026]]*0.8,9.4)*12)-13.5)*0.2975/12 -> 2.4618125
B34: Project Manager | C34: TBH | D34: 18 | E34: 23 | F34: =Table4[[#This Row],[2026]]/140*1000 -> 164.28571 | G34: 1.71 | H34: 1 | I34: =Table4[[#This Row],[2026]]/Table4[[#This Row],[2025 Net]]-1 -> 0.27777778 | J34: =Table4[[#This Row],[2025 Net]]*1.25 -> 22.5 | K34: =Table4[[#This Row],[2025 Net]]*1.15 -> 20.7 | L34: =((MIN(Table4[[#This Row],[2026]]*0.8,9.4)*12)-13.5)*0.2975/12 -> 2.4618125
B35: Mobile Developer 1 | C35: Mina | D35: 25 | E35: 31 | F35: =Table4[[#This Row],[2026]]/140*1000 -> 221.42857 | G35: 2.28 | H35: 1 | I35: =Table4[[#This Row],[2026]]/Table4[[#This Row],[2025 Net]]-1 -> 0.24 | J35: =Table4[[#This Row],[2025 Net]]*1.25 -> 31.25 | K35: =Table4[[#This Row],[2025 Net]]*1.15 -> 28.75 | L35: =((MIN(Table4[[#This Row],[2026]]*0.8,9.4)*12)-13.5)*0.2975/12 -> 2.4618125
B36: Mobile Developer 2 | C36: TBH | D36: 18 | E36: 21 | F36: =Table4[[#This Row],[2026]]/140*1000 -> 150 | G36: =MIN(Table4[[#This Row],[2026]],8.1)*0.2975 -> 2.40975 | H36: 1 | I36: =Table4[[#This Row],[2026]]/Table4[[#This Row],[2025 Net]]-1 -> 0.16666667 | J36: =Table4[[#This Row],[2025 Net]]*1.25 -> 22.5 | K36: =Table4[[#This Row],[2025 Net]]*1.15 -> 20.7 | L36: =((MIN(Table4[[#This Row],[2026]]*0.8,9.4)*12)-13.5)*0.2975/12 -> 2.4618125
B37: Tester | C37: Monad | D37: 14 | E37: 17 | F37: =Table4[[#This Row],[2026]]/140*1000 -> 121.42857 | G37: 1.57 | H37: 1 | I37: =Table4[[#This Row],[2026]]/Table4[[#This Row],[2025 Net]]-1 -> 0.21428571 | J37: =Table4[[#This Row],[2025 Net]]*1.25 -> 17.5 | K37: =Table4[[#This Row],[2025 Net]]*1.15 -> 16.1 | L37: =((MIN(Table4[[#This Row],[2026]]*0.8,9.4)*12)-13.5)*0.2975/12 -> 2.4618125
B38: Tester | C38: Anton | D38: 17 | E38: 20 | F38: =Table4[[#This Row],[2026]]/140*1000 -> 142.85714 | G38: =1.57*0.6 -> 0.942 | H38: 1 | I38: =Table4[[#This Row],[2026]]/Table4[[#This Row],[2025 Net]]-1 -> 0.17647059 | J38: =Table4[[#This Row],[2025 Net]]*1.25 -> 21.25 | K38: =Table4[[#This Row],[2025 Net]]*1.15 -> 19.55 | L38: =((MIN(Table4[[#This Row],[2026]]*0.8,9.4)*12)-13.5)*0.2975/12 -> 2.4618125
B39: Websites Department | J39: =Table4[[#This Row],[2025 Net]]*1.25 -> 0 | K39: =Table4[[#This Row],[2025 Net]]*1.15 -> 0 | L39: =((MIN(Table4[[#This Row],[2026]]*0.8,9.4)*12)-13.5)*0.2975/12 -> -0.3346875
B40: =B26 -> Engineering Manager | C40: =C26 -> Samer | D40: =D19 -> 90 | E40: =E19 -> 104 | F40: =Table4[[#This Row],[2026]]/140*1000 -> 742.85714 | H40: 1 | I40: =Table4[[#This Row],[2026]]/Table4[[#This Row],[2025 Net]]-1 -> 0.15555556 | J40: =Table4[[#This Row],[2025 Net]]*1.25 -> 112.5 | K40: =Table4[[#This Row],[2025 Net]]*1.15 -> 103.5 | L40: =((MIN(Table4[[#This Row],[2026]]*0.8,9.4)*12)-13.5)*0.2975/12 -> 2.4618125
B41: =B28 -> Project Manager | C41: =C28 -> Nathalie | D41: =D28 -> 30 | E41: =E28 -> 35 | F41: =Table4[[#This Row],[2026]]/140*1000 -> 250 | H41: 1 | I41: =Table4[[#This Row],[2026]]/Table4[[#This Row],[2025 Net]]-1 -> 0.16666667 | J41: =Table4[[#This Row],[2025 Net]]*1.25 -> 37.5 | K41: =Table4[[#This Row],[2025 Net]]*1.15 -> 34.5 | L41: =((MIN(Table4[[#This Row],[2026]]*0.8,9.4)*12)-13.5)*0.2975/12 -> 2.4618125
B42: Frontend Designer | C42: Esraa | D42: 20 | E42: 23.5 | F42: =Table4[[#This Row],[2026]]/140*1000 -> 167.85714 | G42: 1.69 | H42: 1 | I42: =Table4[[#This Row],[2026]]/Table4[[#This Row],[2025 Net]]-1 -> 0.175 | J42: =Table4[[#This Row],[2025 Net]]*1.25 -> 25 | K42: =Table4[[#This Row],[2025 Net]]*1.15 -> 23 | L42: =((MIN(Table4[[#This Row],[2026]]*0.8,9.4)*12)-13.5)*0.2975/12 -> 2.4618125
B43: Frontend Developer 1 | C43: Mohamed | D43: 23 | E43: 27 | F43: =Table4[[#This Row],[2026]]/140*1000 -> 192.85714 | G43: =MIN(Table4[[#This Row],[2026]],8.1)*0.2975 -> 2.40975 | H43: 1 | I43: =Table4[[#This Row],[2026]]/Table4[[#This Row],[2025 Net]]-1 -> 0.17391304 | J43: =Table4[[#This Row],[2025 Net]]*1.25 -> 28.75 | K43: =Table4[[#This Row],[2025 Net]]*1.15 -> 26.45 | L43: =((MIN(Table4[[#This Row],[2026]]*0.8,9.4)*12)-13.5)*0.2975/12 -> 2.4618125
...

Sheet OpEx
B2: Aura Systems
B3: OPEX (Other) Forecast
B4: Financial Numbers in 000s of EGP
B6: Inflation | C6: 0.1
B8: OPEX Estimates
B9: Opex item | C9: Cost/Month | D9: Rep | E9: 2025
B10: =[11]OpEx!$B7 -> Rent | C10: =E10*1.1 -> 19965 | D10: 1 | E10: 18150
B11: =[11]OpEx!$B8 -> Consumables | C11: =E11*1.1 -> 7935.9335 | D11: 1 | E11: =AVERAGE([12]OpEx!$C$8:$L$8) -> 7214.485
B12: =[11]OpEx!$B9 -> Office Supplies | C12: =E12*1.1 -> 204.38 | D12: 1 | E12: =AVERAGE([12]OpEx!$C$9:$L$9) -> 185.8
B13: =[11]OpEx!$B10 -> Services | C13: =E13*1.1 -> 794.2 | D13: 1 | E13: =AVERAGE([12]OpEx!$C$10:$L$10) -> 722
B14: =[11]OpEx!$B11 -> Bills | C14: =E14*1.1 -> 660 | D14: 1 | E14: =AVERAGE([12]OpEx!$C$11:$L$11) -> 600
B15: =[11]OpEx!$B12 -> Internet | C15: =E15*1.1 -> 2244.1738 | D15: 1 | E15: =AVERAGE([12]OpEx!$C$12:$L$12) -> 2040.158
B16: =[11]OpEx!$B13 -> Subscriptions | C16: =E16*1.1 -> 44287.868 | D16: 1 | E16: =AVERAGE([12]OpEx!$C$13:$L$13) -> 40261.698
B17: =[11]OpEx!$B14 -> Utilities | C17: =E17*1.1 -> 1935.1354 | D17: 1 | E17: =AVERAGE([12]OpEx!$C$14:$L$14) -> 1759.214
B18: =[11]OpEx!$B15 -> Transportation | C18: =E18*1.1 -> 525.03 | D18: 1 | E18: =AVERAGE([12]OpEx!$C$15:$L$15) -> 477.3
B19: =[11]OpEx!$B16 -> Bank Charges | C19: =E19*1.1 -> 1710.3458 | D19: 1 | E19: =AVERAGE([12]OpEx!$C$16:$L$16) -> 1554.8598
B20: =[11]OpEx!$B17 -> Marketing | C20: =E20*1.1 -> 0 | D20: 1 | E20: =AVERAGE([12]OpEx!$C$17:$L$17) -> 0
B21: =[11]OpEx!$B18 -> Medical | C21: =E21*1.1 -> 9776.8 | D21: 1 | E21: =AVERAGE([12]OpEx!$C$18:$L$18) -> 8888
B22: =[11]OpEx!$B19 -> Courses | C22: =E22*1.1 -> 0 | D22: 1 | E22: =AVERAGE([12]OpEx!$C$19:$L$19) -> 0
B24: OPEX Forecast
C25: 46023 | D25: 46054 | E25: 46082 | F25: 46113 | G25: 46143 | H25: 46174 | I25: 46204 | J25: 46235 | K25: 46266 | L25: 46296 | M25: 46327 | N25: 46357
B26: =B10 -> Rent | C26: 3 | D26: 0 | E26: 0 | F26: 3 | G26: 0 | H26: 0 | I26: 3 | J26: 0 | K26: 0 | L26: 3 | M26: 0 | N26: 0
B27: =B11 -> Consumables | C27: 1 | D27: 1 | E27: 1 | F27: 1 | G27: 1 | H27: 1 | I27: 1 | J27: 1 | K27: 1 | L27: 1 | M27: 1 | N27: 1
B28: =B12 -> Office Supplies | C28: 1 | D28: 1 | E28: 1 | F28: 1 | G28: 1 | H28: 1 | I28: 1 | J28: 1 | K28: 1 | L28: 1 | M28: 1 | N28: 1
B29: =B13 -> Services | C29: 1 | D29: 1 | E29: 1 | F29: 1 | G29: 1 | H29: 1 | I29: 1 | J29: 1 | K29: 1 | L29: 1 | M29: 1 | N29: 1
B30: =B14 -> Bills | C30: 1 | D30: 1 | E30: 1 | F30: 1 | G30: 1 | H30: 1 | I30: 1 | J30: 1 | K30: 1 | L30: 1 | M30: 1 | N30: 1
B31: =B15 -> Internet | C31: 1 | D31: 1 | E31: 1 | F31: 1 | G31: 1 | H31: 1 | I31: 1 | J31: 1 | K31: 1 | L31: 1 | M31: 1 | N31: 1
B32: =B16 -> Subscriptions | C32: 1 | D32: 1 | E32: 1 | F32: 1 | G32: 1 | H32: 1 | I32: 1 | J32: 1 | K32: 1 | L32: 1 | M32: 1 | N32: 1
B33: =B17 -> Utilities | C33: 1 | D33: 1 | E33: 1 | F33: 1 | G33: 1 | H33: 1 | I33: 1 | J33: 1 | K33: 1 | L33: 1 | M33: 1 | N33: 1
B34: =B18 -> Transportation | C34: 1 | D34: 1 | E34: 1 | F34: 1 | G34: 1 | H34: 1 | I34: 1 | J34: 1 | K34: 1 | L34: 1 | M34: 1 | N34: 1
B35: =B19 -> Bank Charges | C35: 1 | D35: 1 | E35: 1 | F35: 1 | G35: 1 | H35: 1 | I35: 1 | J35: 1 | K35: 1 | L35: 1 | M35: 1 | N35: 1
B36: =B20 -> Marketing | C36: 1 | D36: 1 | E36: 1 | F36: 1 | G36: 1 | H36: 1 | I36: 1 | J36: 1 | K36: 1 | L36: 1 | M36: 1 | N36: 1
B37: =B21 -> Medical | C37: 1 | D37: 1 | E37: 1 | F37: 1 | G37: 1 | H37: 1 | I37: 1 | J37: 1 | K37: 1 | L37: 1 | M37: 1 | N37: 1
B38: =B22 -> Courses | C38: 1 | D38: 1 | E38: 1 | F38: 1 | G38: 1 | H38: 1 | I38: 1 | J38: 1 | K38: 1 | L38: 1 | M38: 1 | N38: 1
B40: OPEX Expense
C41: =Personnel!C58 -> 46023 | D41: =Personnel!D58 -> 46054 | E41: =Personnel!E58 -> 46082 | F41: =Personnel!F58 -> 46113 | G41: =Personnel!G58 -> 46143 | H41: =Personnel!H58 -> 46174 | I41: =Personnel!I58 -> 46204 | J41: =Personnel!J58 -> 46235 | ... N41: =Personnel!N58 -> 46357
B42: Cost Increase Coefficient | C42: 1 | D42: =C42 -> 1 | E42: =D42 -> 1 | F42: =E42 -> 1 | G42: =F42 -> 1 | H42: =G42 -> 1 | I42: =H42 -> 1 | J42: =I42 -> 1 | K42: =J42 -> 1 | ... N42: =M42 -> 1 | O42: Total
B43: =B10 -> Rent | C43: =C26*$C10*$D10 -> 59895 | D43: =D26*$C10*$D10*$D$42 -> 0 | E43: =E26*$C10*$D10*$D$42 -> 0 | F43: =F26*$C10*$D10*$D$42 -> 59895 | G43: =G26*$C10*$D10*$D$42 -> 0 | H43: =H26*$C10*$D10*$H$42 -> 0 | I43: =I26*$C10*$D10*$H$42 -> 59895 | J43: =J26*$C10*$D10*$H$42 -> 0 | K43: =K26*$C10*$D10*$H$42 -> 0 | L43: =L26*$C10*$D10*$L$42 -> 59895 | M43: =M26*$C10*$D10*$L$42 -> 0 | N43: =N26*$C10*$D10*$L$42 -> 0 | O43: =SUM(C43:N43) -> 239580
B44: =B11 -> Consumables | C44: =C27*$C11*$D11 -> 7935.9335 | D44: =D27*$C11*$D11*$D$42 -> 7935.9335 | E44: =E27*$C11*$D11*$D$42 -> 7935.9335 | F44: =F27*$C11*$D11*$D$42 -> 7935.9335 | G44: =G27*$C11*$D11*$D$42 -> 7935.9335 | H44: =H27*$C11*$D11*$H$42 -> 7935.9335 | I44: =I27*$C11*$D11*$H$42 -> 7935.9335 | J44: =J27*$C11*$D11*$H$42 -> 7935.9335 | K44: =K27*$C11*$D11*$H$42 -> 7935.9335 | L44: =L27*$C11*$D11*$L$42 -> 7935.9335 | M44: =M27*$C11*$D11*$L$42 -> 7935.9335 | N44: =N27*$C11*$D11*$L$42 -> 7935.9335 | O44: =SUM(C44:N44) -> 95231.202
B45: =B12 -> Office Supplies | C45: =C28*$C12*$D12*C42 -> 204.38 | D45: =D28*$C12*$D12*D42 -> 204.38 | E45: =E28*$C12*$D12*E42 -> 204.38 | F45: =F28*$C12*$D12*F42 -> 204.38 | G45: =G28*$C12*$D12*G42 -> 204.38 | H45: =H28*$C12*$D12*H42 -> 204.38 | I45: =I28*$C12*$D12*I42 -> 204.38 | J45: =J28*$C12*$D12*J42 -> 204.38 | ... N45: =N28*$C12*$D12*N42 -> 204.38 | O45: =SUM(C45:N45) -> 2452.56
...

Sheet Taxes
B2: Aura Systems
B3: Taxes Forecast
B4: Financial Numbers in 000s of EGP
B6: Inflation | C6: 0.15
B8: 2025 Monthly Salaries | C8: ='P&L'!F22/12 -> 400096.34
B9: 2025 Headcount | C9: 17
B10: 2025 Average Salary | C10: =C8/C9 -> 23535.079
B11: 2025 Monthly Payroll Tax | C11: =E21 -> 9618.9945
B12: 2025 Payroll Tax per employee | C12: =C11/C9 -> 565.82321
B13: 2026 Monthly Salaries | C13: =AVERAGE(Personnel!C152:N152)*1000 -> 521750
B14: 2026 Headcount | C14: 17
B15: 2026 Average Salary | C15: =C13/C14 -> 30691.176
B16: 2026 Salaries Increase | C16: 1.16
B18: Taxes Estimates
B19: Opex item | C19: Cost/Month | D19: Rep | E19: 2025
B20: =[11]Taxes!$B7 -> Deduction Tax | C20: =Result!I15*0 -> 0 | D20: 1 | E20: =AVERAGEA([12]Taxes!$C$7:$M$7) -> 16106.623
B21: =[11]Taxes!$B8 -> Payroll Tax | C21: =C12*C16*C14*1.1 -> 12273.837 | D21: 1 | E21: =AVERAGE([12]Taxes!$C$8:$M$8) -> 9618.9945
B22: =[11]Taxes!$B9 -> Income Tax | C22: =SUM(Result!H15*0.015)/12 -> 19250 | D22: 1 | E22: 0
B23: =[11]Taxes!$B11 -> Social Insurance | C23: =(35000*12+725000)/12 -> 95416.667 | D23: 1 | E23: =1250000/12 -> 104166.67
B25: Taxes Forecast
C26: =Personnel!C58 -> 46023 | D26: =Personnel!D58 -> 46054 | E26: =Personnel!E58 -> 46082 | F26: =Personnel!F58 -> 46113 | G26: =Personnel!G58 -> 46143 | H26: =Personnel!H58 -> 46174 | I26: =Personnel!I58 -> 46204 | J26: =Personnel!J58 -> 46235 | ... N26: =Personnel!N58 -> 46357
B27: =B20 -> Deduction Tax | C27: 1 | D27: 1 | E27: 1 | F27: 1 | G27: 1 | H27: 1 | I27: 1 | J27: 1 | K27: 1 | L27: 1 | M27: 1 | N27: 1
B28: =B21 -> Payroll Tax | C28: 1 | D28: 1 | E28: 1 | F28: 1 | G28: 1 | H28: 1 | I28: 1 | J28: 1 | K28: 1 | L28: 1 | M28: 1 | N28: 1
B29: =B22 -> Income Tax | C29: 1 | D29: 1 | E29: 1 | F29: 1 | G29: 1 | H29: 1 | I29: 1 | J29: 1 | K29: 1 | L29: 1 | M29: 1 | N29: 1
B30: =B23 -> Social Insurance | C30: 1 | D30: 1 | E30: 1 | F30: 1 | G30: 1 | H30: 1 | I30: 1 | J30: 1 | K30: 1 | L30: 1 | M30: 1 | N30: 1
B32: Taxes Expense
C33: =C26 -> 46023 | D33: =D26 -> 46054 | E33: =E26 -> 46082 | F33: =F26 -> 46113 | G33: =G26 -> 46143 | H33: =H26 -> 46174 | I33: =I26 -> 46204 | J33: =J26 -> 46235 | ... N33: =N26 -> 46357
B34: Cost Increase Coefficient | C34: 1 | D34: =C34 -> 1 | E34: =D34 -> 1 | F34: =E34 -> 1 | G34: =F34 -> 1 | H34: =G34 -> 1 | I34: =H34 -> 1 | J34: =I34 -> 1 | K34: =J34 -> 1 | ... N34: =M34 -> 1 | O34: Total
B35: =B20 -> Deduction Tax | C35: =C27*$C20*$D20 -> 0 | D35: =D27*$C20*$D20*$D$34 -> 0 | E35: =E27*$C20*$D20*$D$34 -> 0 | F35: =F27*$C20*$D20*$D$34 -> 0 | G35: =G27*$C20*$D20*$D$34 -> 0 | H35: =H27*$C20*$D20*$H$34 -> 0 | I35: =I27*$C20*$D20*$H$34 -> 0 | J35: =J27*$C20*$D20*$H$34 -> 0 | K35: =K27*$C20*$D20*$H$34 -> 0 | L35: =L27*$C20*$D20*$L$34 -> 0 | M35: =M27*$C20*$D20*$L$34 -> 0 | N35: =N27*$C20*$D20*$L$34 -> 0 | O35: =SUM(C35:N35) -> 0
B36: =B21 -> Payroll Tax | C36: =C28*$C21*$D21 -> 12273.837 | D36: =D28*$C21*$D21*$D$34 -> 12273.837 | E36: =E28*$C21*$D21*$D$34 -> 12273.837 | F36: =F28*$C21*$D21*$D$34 -> 12273.837 | G36: =G28*$C21*$D21*$D$34 -> 12273.837 | H36: =H28*$C21*$D21*$H$34 -> 12273.837 | I36: =I28*$C21*$D21*$H$34 -> 12273.837 | J36: =J28*$C21*$D21*$H$34 -> 12273.837 | K36: =K28*$C21*$D21*$H$34 -> 12273.837 | L36: =L28*$C21*$D21*$L$34 -> 12273.837 | M36: =M28*$C21*$D21*$L$34 -> 12273.837 | N36: =N28*$C21*$D21*$L$34 -> 12273.837 | O36: =SUM(C36:N36) -> 147286.04
B37: =B22 -> Income Tax | C37: =C29*$C22*$D22 -> 19250 | D37: =D29*$C22*$D22*$D$34 -> 19250 | E37: =E29*$C22*$D22 -> 19250 | F37: =F29*$C22*$D22 -> 19250 | G37: =G29*$C22*$D22 -> 19250 | H37: =H29*$C22*$D22 -> 19250 | I37: =I29*$C22*$D22 -> 19250 | J37: =J29*$C22*$D22 -> 19250 | K37: =K29*$C22*$D22 -> 19250 | L37: =L29*$C22*$D22 -> 19250 | ... N37: =N29*$C22*$D22 -> 19250 | O37: =SUM(C37:N37) -> 231000
B38: =B23 -> Social Insurance | C38: =C30*$C23*$D23 -> 95416.667 | D38: =D30*$C23*$D23*$D$34 -> 95416.667 | E38: =E30*$C23*$D23*$D$34 -> 95416.667 | F38: =F30*$C23*$D23*$D$34 -> 95416.667 | G38: =G30*$C23*$D23*$D$34 -> 95416.667 | H38: =H30*$C23*$D23*$H$34 -> 95416.667 | I38: =I30*$C23*$D23*$H$34 -> 95416.667 | J38: =J30*$C23*$D23*$H$34 -> 95416.667 | K38: =K30*$C23*$D23*$H$34 -> 95416.667 | L38: =L30*$C23*$D23*$L$34 -> 95416.667 | M38: =M30*$C23*$D23*$L$34 -> 95416.667 | N38: =N30*$C23*$D23*$L$34 -> 95416.667 | O38: =SUM(C38:N38) -> 1145000
B39: Total Other OPEX | C39: =SUM(C35:C38) -> 126940.5 | D39: =SUM(D35:D38) -> 126940.5 | E39: =SUM(E35:E38) -> 126940.5 | F39: =SUM(F35:F38) -> 126940.5 | G39: =SUM(G35:G38) -> 126940.5 | H39: =SUM(H35:H38) -> 126940.5 | I39: =SUM(I35:I38) -> 126940.5 | J39: =SUM(J35:J38) -> 126940.5 | ... N39: =SUM(N35:N38) -> 126940.5 | O39: =SUM(C39:N39) -> 1523286

Sheet P&L
B2: Aura Systems - Software Department
B3: P&L Budget
B4: Financial Numbers in EGP
B6: P&L | D6: 2026 | F6: 2025
B7: Item | C7: % | E7: %
B8: Revenue
B9: =Result!B7 -> Products | C9: =D9/D17 -> 0.16233766 | D9: =Result!H7 -> 2500000 | E9: =F9/$F$17 -> 0.17598812 | F9: =Growth!M7 -> 2140293.1
B10: =Result!B8 -> PHP | C10: =D10/$D$17 -> 0.31168831 | D10: =Result!H8 -> 4800000 | E10: =F10/$F$17 -> 0.30248736 | F10: =Growth!M8 -> 3678723.6
B11: .NET | C11: =D11/$D$17 -> 0.27272727 | D11: =Result!H9 -> 4200000 | E11: =F11/$F$17 -> 0.28898985 | F11: =Growth!M9 -> 3514572.5
B12: =Result!B10 -> Mobile Development | C12: =D12/$D$17 -> 0.12987013 | D12: =Result!H10 -> 2000000 | E12: =F12/$F$17 -> 0.11863489 | F12: =Growth!M10 -> 1442787.5
B13: =Result!B11 -> Support Contracts | C13: =D13/$D$17 -> 0 | D13: =Result!H11 -> 0 | E13: =F13/$F$17 -> 0 | F13: =Growth!M11 -> 0
B14: =Result!B12 -> Websites | C14: =D14/$D$17 -> 0.071428571 | D14: =Result!H12 -> 1100000 | E14: =F14/$F$17 -> 0.057089092 | F14: =Growth!M12 -> 694293.43
B15: Design | C15: =D15/$D$17 -> 0.027272727 | D15: =Result!H13 -> 420000 | E15: =F15/$F$17 -> 0.025825471 | F15: =Growth!M13 -> 314078.48
B16: =Result!B14 -> Hosting | C16: =D16/$D$17 -> 0.024675325 | D16: =Result!H14 -> 380000 | E16: =F16/$F$17 -> 0.030985223 | F16: =Growth!M14 -> 376829.19
B17: Total Sales | C17: =SUM(C9:C16) -> 1 | D17: =SUM(D9:D16) -> 15400000 | E17: =F17/$F$17 -> 1 | F17: =SUM(F9:F16) -> 12161578
B18: Cost of Sales | C18: 0.07 | D18: =C18*D17 -> 1078000 | E18: =F18/F17 -> 0.13640457 | F18: ='[13]I&E'!$AF$28/11*12 -> 1658894.8
B19: VAT | C19: 0.12 | D19: =D17*C19 -> 1848000 | E19: =F19/F17 -> 0.096535485 | F19: ='[13]I&E'!$AF$34/10*12 -> 1174023.8
B20: Gross Profit | C20: =D20/D17 -> 0.81 | D20: =D17-D18-D19 -> 12474000 | E20: =F20/F17 -> 0.76705994 | F20: =F17-F18-F19 -> 9328659.1
B21: Other Direct Expenses
B22: Salaries | C22: =D22/D20 -> 0.47190957 | D22: =Personnel!O152*1000-SUM(Personnel!C111:N111)*1000 -> 5886600 | E22: =F22/F20 -> 0.51466733 | F22: ='[12]Expenses 2k25'!$O$8/11*12 -> 4801156.1
B23: Sales Commissions | C23: =D23/D20 -> 0.0040083373 | D23: 50000 | E23: =F23/F20 -> 0 | F23: 0
B24: Earnings | C24: =D24/D20 -> 0.52408209 | D24: =D20-SUM(D22:D23) -> 6537400 | E24: =F24/F20 -> 0.48533267 | F24: =F20-SUM(F22:F23) -> 4527503.1
B25: Contribution
B26: G&A Salaries | C26: =D26/D20 -> 0.087734488 | D26: =Personnel!O117*1000 -> 1094400 | E26: =F26/F20 -> 0.090297525 | F26: =[14]Summary!$BD$23/11*12 -> 842354.83
B27: OpEx | C27: 0.08 | D27: =D17*C27 -> 1232000 | E27: 0.066 | F27: ='[12]Expenses 2k25'!$O$9 -> 864198.12
B28: Taxes | C28: =D28/D20 -> 0.12211689 | D28: =Taxes!O39 -> 1523286 | E28: =F28/F20 -> 0.19694395 | F28: ='[12]Expenses 2k25'!$O$13 -> 1837223
B29: Profit | C29: =D29/D20 -> 0.21546528 | D29: =D24-D26-D27-D28 -> 2687714 | E29: =F29/F20 -> 0.10545215 | F29: =F24-F26-F27-F28 -> 983727.14
B30: CapEx
B33: Sales Commissions
B34: Activity | C34: Percent
B35: =B9 -> Products | C35: 0.1
B36: =B10 -> PHP | C36: 0.03
B37: .Net | C37: 0
B38: =B12 -> Mobile Development | C38: 0.03
B39: =B13 -> Support Contracts | C39: 0.03
B40: =B14 -> Websites | C40: 0.06
B41: Design | C41: 0.06
B42: =B16 -> Hosting | C42: 0

Sheet CapEx
B2: Aura Systems
B3: CapEx Forecast
B4: Financial Numbers in EGP
B7: CapEx Estimates
B8: CapEx item | C8: Cost | D8: Rep
B9: Laptop | C9: 40000 | D9: 1
B10: SSD | C10: 2000 | D10: 1
B11: Nnetwork Booster | C11: 6000 | D11: 1
B12: Move | C12: 3000 | D12: 1
D13: 1
D14: 1
D15: 1
D16: 1
D17: 1
D18: 1
D19: 1
D20: 1
D21: 1
D22: 1
D23: 1
D24: 1
... D35: 1
B37: CapEx Forecast
C38: 46023 | D38: 46054 | E38: 46082 | F38: 46113 | G38: 46143 | H38: 46174 | I38: 46204 | J38: 46235 | K38: 46266 | L38: 46296 | M38: 46327 | N38: 46357
B39: Headcount | C39: ='[15]Personnel Forecast'!C106 -> 23.75 | D39: ='[15]Personnel Forecast'!D106 -> 26.75 | E39: ='[15]Personnel Forecast'!E106 -> 27.75 | F39: ='[15]Personnel Forecast'!F106 -> 28.75 | G39: ='[15]Personnel Forecast'!G106 -> 28.75 | H39: ='[15]Personnel Forecast'!H106 -> 29.75 | I39: ='[15]Personnel Forecast'!I106 -> 32.75 | J39: ='[15]Personnel Forecast'!J106 -> 32.75 | ... N39: ='[15]Personnel Forecast'!N106 -> 32.75
B40: =B9 -> Laptop
B41: =B10 -> SSD
B42: =B11 -> Nnetwork Booster
B43: =B12 -> Move
B44: =B13 -> 0
B45: =B14 -> 0
B46: =B15 -> 0
B47: =B16 -> 0
B48: =B17 -> 0
B49: =B18 -> 0
B50: =B19 -> 0
B51: =B20 -> 0
... B66: =B35 -> 0
B68: CapEx Forecast
C69: =C38 -> 46023 | D69: =D38 -> 46054 | E69: =E38 -> 46082 | F69: =F38 -> 46113 | G69: =G38 -> 46143 | H69: =H38 -> 46174 | I69: =I38 -> 46204 | J69: =J38 -> 46235 | ... N69: =N38 -> 46357
...
